Workbook

Sheet Results
A1: Hshld_code | B1: Hshld_subcode | C1: house_type | D1: insulation | E1: Loc_code | F1: SH_code | G1: DW_code | H1: HP_cap | I1: R_cap | J1: Hyd_Cap_kW_Adj | K1: Tank_Volume (L) | L1: Manufacture | M1: Hyd_Manufacture_HP | N1: Hyd_Manufacture_Tank | O1: Hyd_Manufacture_FC | P1: Hyd_Manufacture | Q1: Distribution | R1: Installation | S1: EOL | T1: Other | U1: EOL_S | V1: Other_S | W1: Manufacture_MJ | X1: Hyd_Manufacture_MJ_HP | Y1: Hyd_Manufacture_MJ_Tank | Z1: Hyd_Manufacture_MJ_FC | AA1: Hyd_Manufacture_MJ | AB1: Distribution_MJ | AC1: Installation_MJ | AD1: EOL_MJ | AE1: Other_MJ | AG1: PLEASE DO NOT CHANGE CODE IN CELLS. BE AWARE THAT CODE DOES NOT NECESSARILY APPLIES TO ALL CELLS WITHIN A COLUMN; THEY ARE CASE/SCENARIO SPECIFIC. CELLS IN BLUE CAN BE COPIED AS VALUES (NO FORMAT OR FORMULAS) TO A CSV FILE TO BE USED FOR FURTHER PROCESSING WITH TECHNOLOGIES.CSV
A2: Mass-Nom-Real | B2: =_xlfn.TEXTBEFORE(A2, "-", 2) -> Mass-Nom | C2: =_xlfn.TEXTBEFORE(A2, "-", 1) -> Mass | D2: =_xlfn.TEXTAFTER(B2, "-", 1) -> Nom | E2: AK | F2: R | I2: {=_xlfn.SWITCH(F2,"R",_xlfn.XLOOKUP(E2&"|"&B2, Calculate_cap_emi!$I$14:$I$21&"|"&Calculate_cap_emi!$L$14:$L$21, Calculate_cap_emi!$W$14:$W$21, "Not found", 0),"Rb",_xlfn.XLOOKUP(E2&"|"&B2, Calculate_cap_emi!$I$14:$I$21&"|"&Calculate_cap_emi!$L$14:$L$21, Calculate_cap_emi!$Y$14:$Y$21, "Not found", 0),"Rl",_xlfn.XLOOKUP(E2&"|"&B2, Calculate_cap_emi!$I$14:$I$21&"|"&Calculate_cap_emi!$L$14:$L$21, Calculate_cap_emi!$Z$14:$Z$21, "Not found", 0),0)} -> 11 | L2: {=_xlfn.SWITCH(F2,"R",_xlfn.XLOOKUP(E2&"|"&B2, Calculate_cap_emi!$I$14:$I$21&"|"&Calculate_cap_emi!$L$14:$L$21, Calculate_cap_emi!$AC$14:$AC$21, "Not found", 0),"Rb",_xlfn.XLOOKUP(E2&"|"&B2, Calculate_cap_emi!$I$14:$I$21&"|"&Calculate_cap_emi!$L$14:$L$21, Calculate_cap_emi!$AE$14:$AE$21, "Not found", 0),"Rl",_xlfn.XLOOKUP(E2&"|"&B2, Calculate_cap_emi!$I$14:$I$21&"|"&Calculate_cap_emi!$L$14:$L$21, Calculate_cap_emi!$AF$14:$AF$21, "Not found", 0),"HP",_xlfn.XLOOKUP(E2&"|"&B2, Calculate_cap_emi!$I$14:$I$21&"|"&Calculate_cap_emi!$L$14:$L$21, Calculate_cap_emi!$AD$14:$AD$21, "Not found", 0),"HPl",_xlfn.XLOOKUP(E2&"|"&B2, Calculate_cap_emi!$I$14:$I$21&"|"&Calculate_cap_emi!$L$14:$L$21, Calculate_cap_emi!$AG$14:$AG$21, "Not found", 0),"Missing")} -> 945.7181 | Q2: {=_xlfn.SWITCH(F2,"R",_xlfn.XLOOKUP(E2&"|"&B2, Calculate_cap_emi!$I$14:$I$21&"|"&Calculate_cap_emi!$L$14:$L$21, Calculate_cap_emi!$AJ$14:$AJ$21, "Not found", 0),"Rb",_xlfn.XLOOKUP(E2&"|"&B2, Calculate_cap_emi!$I$14:$I$21&"|"&Calculate_cap_emi!$L$14:$L$21, Calculate_cap_emi!$AL$14:$AL$21, "Not found", 0),"Rl",_xlfn.XLOOKUP(E2&"|"&B2, Calculate_cap_emi!$I$14:$I$21&"|"&Calculate_cap_emi!$L$14:$L$21, Calculate_cap_emi!$AM$14:$AM$21, "Not found", 0),"HP",_xlfn.XLOOKUP(E2&"|"&B2, Calculate_cap_emi!$I$14:$I$21&"|"&Calculate_cap_emi!$L$14:$L$21, Calculate_cap_emi!$AK$14:$AK$21, "Not found", 0),"HPl",_xlfn.XLOOKUP(E2&"|"&B2, Calculate_cap_emi!$I$14:$I$21&"|"&Calculate_cap_emi!$L$14:$L$21, Calculate_cap_emi!$AN$14:$AN$21, "Not found", 0),"Missing")} -> 46.407925 | R2: {=_xlfn.SWITCH(F2,"R",_xlfn.XLOOKUP(E2&"|"&B2, Calculate_cap_emi!$I$14:$I$21&"|"&Calculate_cap_emi!$L$14:$L$21, Calculate_cap_emi!$AQ$14:$AQ$21, "Not found", 0),"Rb",_xlfn.XLOOKUP(E2&"|"&B2, Calculate_cap_emi!$I$14:$I$21&"|"&Calculate_cap_emi!$L$14:$L$21, Calculate_cap_emi!$AS$14:$AS$21, "Not found", 0),"Rl",_xlfn.XLOOKUP(E2&"|"&B2, Calculate_cap_emi!$I$14:$I$21&"|"&Calculate_cap_emi!$L$14:$L$21, Calculate_cap_emi!$AT$14:$AT$21, "Not found", 0),"HP",_xlfn.XLOOKUP(E2&"|"&B2, Calculate_cap_emi!$I$14:$I$21&"|"&Calculate_cap_emi!$L$14:$L$21, Calculate_cap_emi!$AR$14:$AR$21, "Not found", 0),"HPl",_xlfn.XLOOKUP(E2&"|"&B2, Calculate_cap_emi!$I$14:$I$21&"|"&Calculate_cap_emi!$L$14:$L$21, Calculate_cap_emi!$AU$14:$AU$21, "Not found", 0),"Missing")} -> 4.697462 | S2: {=_xlfn.SWITCH(F2,"R",_xlfn.XLOOKUP(E2&"|"&B2, Calculate_cap_emi!$I$14:$I$21&"|"&Calculate_cap_emi!$L$14:$L$21, Calculate_cap_emi!$AX$14:$AX$21, "Not found", 0),"Rb",_xlfn.XLOOKUP(E2&"|"&B2, Calculate_cap_emi!$I$14:$I$21&"|"&Calculate_cap_emi!$L$14:$L$21, Calculate_cap_emi!$AZ$14:$AZ$21, "Not found", 0),"Rl",_xlfn.XLOOKUP(E2&"|"&B2, Calculate_cap_emi!$I$14:$I$21&"|"&Calculate_cap_emi!$L$14:$L$21, Calculate_cap_emi!$BA$14:$BA$21, "Not found", 0),"HP",_xlfn.XLOOKUP(E2&"|"&B2, Calculate_cap_emi!$I$14:$I$21&"|"&Calculate_cap_emi!$L$14:$L$21, Calculate_cap_emi!$AY$14:$AY$21, "Not found", 0),"HPl",_xlfn.XLOOKUP(E2&"|"&B2, Calculate_cap_emi!$I$14:$I$21&"|"&Calculate_cap_emi!$L$14:$L$21, Calculate_cap_emi!$BB$14:$BB$21, "Not found", 0),"Missing")} -> 54.923037 | T2: {=_xlfn.SWITCH(F2,"R",_xlfn.XLOOKUP(E2&"|"&B2, Calculate_cap_emi!$I$14:$I$21&"|"&Calculate_cap_emi!$L$14:$L$21, Calculate_cap_emi!$BE$14:$BE$21, "Not found", 0),"Rb",_xlfn.XLOOKUP(E2&"|"&B2, Calculate_cap_emi!$I$14:$I$21&"|"&Calculate_cap_emi!$L$14:$L$21, Calculate_cap_emi!$BG$14:$BG$21, "Not found", 0),"Rl",_xlfn.XLOOKUP(E2&"|"&B2, Calculate_cap_emi!$I$14:$I$21&"|"&Calculate_cap_emi!$L$14:$L$21, Calculate_cap_emi!$BH$14:$BH$21, "Not found", 0),"HP",_xlfn.XLOOKUP(E2&"|"&B2, Calculate_cap_emi!$I$14:$I$21&"|"&Calculate_cap_emi!$L$14:$L$21, Calculate_cap_emi!$BF$14:$BF$21, "Not found", 0),"HPl",_xlfn.XLOOKUP(E2&"|"&B2, Calculate_cap_emi!$I$14:$I$21&"|"&Calculate_cap_emi!$L$14:$L$21, Calculate_cap_emi!$BI$14:$BI$21, "Not found", 0),"Missing")} -> 0 | U2: {=_xlfn.SWITCH(F2,"R",_xlfn.XLOOKUP(E2&"|"&B2, Calculate_cap_emi_sens!$I$14:$I$21&"|"&Calculate_cap_emi_sens!$L$14:$L$21, Calculate_cap_emi_sens!$AX$14:$AX$21, "Not found", 0),"Rb",_xlfn.XLOOKUP(E2&"|"&B2, Calculate_cap_emi_sens!$I$14:$I$21&"|"&Calculate_cap_emi_sens!$L$14:$L$21, Calculate_cap_emi_sens!$AZ$14:$AZ$21, "Not found", 0),"Rl",_xlfn.XLOOKUP(E2&"|"&B2, Calculate_cap_emi_sens!$I$14:$I$21&"|"&Calculate_cap_emi_sens!$L$14:$L$21, Calculate_cap_emi_sens!$BA$14:$BA$21, "Not found", 0),"HP",_xlfn.XLOOKUP(E2&"|"&B2, Calculate_cap_emi_sens!$I$14:$I$21&"|"&Calculate_cap_emi_sens!$L$14:$L$21, Calculate_cap_emi_sens!$AY$14:$AY$21, "Not found", 0),"HPl",_xlfn.XLOOKUP(E2&"|"&B2, Calculate_cap_emi_sens!$I$14:$I$21&"|"&Calculate_cap_emi_sens!$L$14:$L$21, Calculate_cap_emi_sens!$BB$14:$BB$21, "Not found", 0),"Missing")} -> 54.923037 | V2: {=_xlfn.SWITCH(F2,"R",_xlfn.XLOOKUP(E2&"|"&B2, Calculate_cap_emi_sens!$I$14:$I$21&"|"&Calculate_cap_emi_sens!$L$14:$L$21, Calculate_cap_emi_sens!$BE$14:$BE$21, "Not found", 0),"Rb",_xlfn.XLOOKUP(E2&"|"&B2, Calculate_cap_emi_sens!$I$14:$I$21&"|"&Calculate_cap_emi_sens!$L$14:$L$21, Calculate_cap_emi_sens!$BG$14:$BG$21, "Not found", 0),"Rl",_xlfn.XLOOKUP(E2&"|"&B2, Calculate_cap_emi_sens!$I$14:$I$21&"|"&Calculate_cap_emi_sens!$L$14:$L$21, Calculate_cap_emi_sens!$BH$14:$BH$21, "Not found", 0),"HP",_xlfn.XLOOKUP(E2&"|"&B2, Calculate_cap_emi_sens!$I$14:$I$21&"|"&Calculate_cap_emi_sens!$L$14:$L$21, Calculate_cap_emi_sens!$BF$14:$BF$21, "Not found", 0),"HPl",_xlfn.XLOOKUP(E2&"|"&B2, Calculate_cap_emi_sens!$I$14:$I$21&"|"&Calculate_cap_emi_sens!$L$14:$L$21, Calculate_cap_emi_sens!$BI$14:$BI$21, "Not found", 0),"Missing")} -> 0 | W2: =Results_proc_ener!L2 -> 24893.256 | X2: =Results_proc_ener!M2 -> 0 | Y2: =Results_proc_ener!N2 -> 0 | Z2: =Results_proc_ener!O2 -> 0 | AA2: =Results_proc_ener!P2 -> 0 | AB2: =Results_proc_ener!Q2 -> 982.85692 | AC2: =Results_proc_ener!R2 -> 17.878346 | AD2: =Results_proc_ener!S2 -> 101.62591 | AE2: =Results_proc_ener!T2 -> 0
A3: Mass-Nom-Ideal | B3: =_xlfn.TEXTBEFORE(A3, "-", 2) -> Mass-Nom | C3: =_xlfn.TEXTBEFORE(A3, "-", 1) -> Mass | D3: =_xlfn.TEXTAFTER(B3, "-", 1) -> Nom | E3: AK | F3: R | I3: {=_xlfn.SWITCH(F3,"R",_xlfn.XLOOKUP(E3&"|"&B3, Calculate_cap_emi!$I$14:$I$21&"|"&Calculate_cap_emi!$L$14:$L$21, Calculate_cap_emi!$W$14:$W$21, "Not found", 0),"Rb",_xlfn.XLOOKUP(E3&"|"&B3, Calculate_cap_emi!$I$14:$I$21&"|"&Calculate_cap_emi!$L$14:$L$21, Calculate_cap_emi!$Y$14:$Y$21, "Not found", 0),"Rl",_xlfn.XLOOKUP(E3&"|"&B3, Calculate_cap_emi!$I$14:$I$21&"|"&Calculate_cap_emi!$L$14:$L$21, Calculate_cap_emi!$Z$14:$Z$21, "Not found", 0),0)} -> 11 | L3: {=_xlfn.SWITCH(F3,"R",_xlfn.XLOOKUP(E3&"|"&B3, Calculate_cap_emi!$I$14:$I$21&"|"&Calculate_cap_emi!$L$14:$L$21, Calculate_cap_emi!$AC$14:$AC$21, "Not found", 0),"Rb",_xlfn.XLOOKUP(E3&"|"&B3, Calculate_cap_emi!$I$14:$I$21&"|"&Calculate_cap_emi!$L$14:$L$21, Calculate_cap_emi!$AE$14:$AE$21, "Not found", 0),"Rl",_xlfn.XLOOKUP(E3&"|"&B3, Calculate_cap_emi!$I$14:$I$21&"|"&Calculate_cap_emi!$L$14:$L$21, Calculate_cap_emi!$AF$14:$AF$21, "Not found", 0),"HP",_xlfn.XLOOKUP(E3&"|"&B3, Calculate_cap_emi!$I$14:$I$21&"|"&Calculate_cap_emi!$L$14:$L$21, Calculate_cap_emi!$AD$14:$AD$21, "Not found", 0),"HPl",_xlfn.XLOOKUP(E3&"|"&B3, Calculate_cap_emi!$I$14:$I$21&"|"&Calculate_cap_emi!$L$14:$L$21, Calculate_cap_emi!$AG$14:$AG$21, "Not found", 0),"Missing")} -> 945.7181 | Q3: {=_xlfn.SWITCH(F3,"R",_xlfn.XLOOKUP(E3&"|"&B3, Calculate_cap_emi!$I$14:$I$21&"|"&Calculate_cap_emi!$L$14:$L$21, Calculate_cap_emi!$AJ$14:$AJ$21, "Not found", 0),"Rb",_xlfn.XLOOKUP(E3&"|"&B3, Calculate_cap_emi!$I$14:$I$21&"|"&Calculate_cap_emi!$L$14:$L$21, Calculate_cap_emi!$AL$14:$AL$21, "Not found", 0),"Rl",_xlfn.XLOOKUP(E3&"|"&B3, Calculate_cap_emi!$I$14:$I$21&"|"&Calculate_cap_emi!$L$14:$L$21, Calculate_cap_emi!$AM$14:$AM$21, "Not found", 0),"HP",_xlfn.XLOOKUP(E3&"|"&B3, Calculate_cap_emi!$I$14:$I$21&"|"&Calculate_cap_emi!$L$14:$L$21, Calculate_cap_emi!$AK$14:$AK$21, "Not found", 0),"HPl",_xlfn.XLOOKUP(E3&"|"&B3, Calculate_cap_emi!$I$14:$I$21&"|"&Calculate_cap_emi!$L$14:$L$21, Calculate_cap_emi!$AN$14:$AN$21, "Not found", 0),"Missing")} -> 46.407925 | R3: {=_xlfn.SWITCH(F3,"R",_xlfn.XLOOKUP(E3&"|"&B3, Calculate_cap_emi!$I$14:$I$21&"|"&Calculate_cap_emi!$L$14:$L$21, Calculate_cap_emi!$AQ$14:$AQ$21, "Not found", 0),"Rb",_xlfn.XLOOKUP(E3&"|"&B3, Calculate_cap_emi!$I$14:$I$21&"|"&Calculate_cap_emi!$L$14:$L$21, Calculate_cap_emi!$AS$14:$AS$21, "Not found", 0),"Rl",_xlfn.XLOOKUP(E3&"|"&B3, Calculate_cap_emi!$I$14:$I$21&"|"&Calculate_cap_emi!$L$14:$L$21, Calculate_cap_emi!$AT$14:$AT$21, "Not found", 0),"HP",_xlfn.XLOOKUP(E3&"|"&B3, Calculate_cap_emi!$I$14:$I$21&"|"&Calculate_cap_emi!$L$14:$L$21, Calculate_cap_emi!$AR$14:$AR$21, "Not found", 0),"HPl",_xlfn.XLOOKUP(E3&"|"&B3, Calculate_cap_emi!$I$14:$I$21&"|"&Calculate_cap_emi!$L$14:$L$21, Calculate_cap_emi!$AU$14:$AU$21, "Not found", 0),"Missing")} -> 4.697462 | S3: {=_xlfn.SWITCH(F3,"R",_xlfn.XLOOKUP(E3&"|"&B3, Calculate_cap_emi!$I$14:$I$21&"|"&Calculate_cap_emi!$L$14:$L$21, Calculate_cap_emi!$AX$14:$AX$21, "Not found", 0),"Rb",_xlfn.XLOOKUP(E3&"|"&B3, Calculate_cap_emi!$I$14:$I$21&"|"&Calculate_cap_emi!$L$14:$L$21, Calculate_cap_emi!$AZ$14:$AZ$21, "Not found", 0),"Rl",_xlfn.XLOOKUP(E3&"|"&B3, Calculate_cap_emi!$I$14:$I$21&"|"&Calculate_cap_emi!$L$14:$L$21, Calculate_cap_emi!$BA$14:$BA$21, "Not found", 0),"HP",_xlfn.XLOOKUP(E3&"|"&B3, Calculate_cap_emi!$I$14:$I$21&"|"&Calculate_cap_emi!$L$14:$L$21, Calculate_cap_emi!$AY$14:$AY$21, "Not found", 0),"HPl",_xlfn.XLOOKUP(E3&"|"&B3, Calculate_cap_emi!$I$14:$I$21&"|"&Calculate_cap_emi!$L$14:$L$21, Calculate_cap_emi!$BB$14:$BB$21, "Not found", 0),"Missing")} -> 54.923037 | T3: {=_xlfn.SWITCH(F3,"R",_xlfn.XLOOKUP(E3&"|"&B3, Calculate_cap_emi!$I$14:$I$21&"|"&Calculate_cap_emi!$L$14:$L$21, Calculate_cap_emi!$BE$14:$BE$21, "Not found", 0),"Rb",_xlfn.XLOOKUP(E3&"|"&B3, Calculate_cap_emi!$I$14:$I$21&"|"&Calculate_cap_emi!$L$14:$L$21, Calculate_cap_emi!$BG$14:$BG$21, "Not found", 0),"Rl",_xlfn.XLOOKUP(E3&"|"&B3, Calculate_cap_emi!$I$14:$I$21&"|"&Calculate_cap_emi!$L$14:$L$21, Calculate_cap_emi!$BH$14:$BH$21, "Not found", 0),"HP",_xlfn.XLOOKUP(E3&"|"&B3, Calculate_cap_emi!$I$14:$I$21&"|"&Calculate_cap_emi!$L$14:$L$21, Calculate_cap_emi!$BF$14:$BF$21, "Not found", 0),"HPl",_xlfn.XLOOKUP(E3&"|"&B3, Calculate_cap_emi!$I$14:$I$21&"|"&Calculate_cap_emi!$L$14:$L$21, Calculate_cap_emi!$BI$14:$BI$21, "Not found", 0),"Missing")} -> 0 | U3: {=_xlfn.SWITCH(F3,"R",_xlfn.XLOOKUP(E3&"|"&B3, Calculate_cap_emi_sens!$I$14:$I$21&"|"&Calculate_cap_emi_sens!$L$14:$L$21, Calculate_cap_emi_sens!$AX$14:$AX$21, "Not found", 0),"Rb",_xlfn.XLOOKUP(E3&"|"&B3, Calculate_cap_emi_sens!$I$14:$I$21&"|"&Calculate_cap_emi_sens!$L$14:$L$21, Calculate_cap_emi_sens!$AZ$14:$AZ$21, "Not found", 0),"Rl",_xlfn.XLOOKUP(E3&"|"&B3, Calculate_cap_emi_sens!$I$14:$I$21&"|"&Calculate_cap_emi_sens!$L$14:$L$21, Calculate_cap_emi_sens!$BA$14:$BA$21, "Not found", 0),"HP",_xlfn.XLOOKUP(E3&"|"&B3, Calculate_cap_emi_sens!$I$14:$I$21&"|"&Calculate_cap_emi_sens!$L$14:$L$21, Calculate_cap_emi_sens!$AY$14:$AY$21, "Not found", 0),"HPl",_xlfn.XLOOKUP(E3&"|"&B3, Calculate_cap_emi_sens!$I$14:$I$21&"|"&Calculate_cap_emi_sens!$L$14:$L$21, Calculate_cap_emi_sens!$BB$14:$BB$21, "Not found", 0),"Missing")} -> 54.923037 | V3: {=_xlfn.SWITCH(F3,"R",_xlfn.XLOOKUP(E3&"|"&B3, Calculate_cap_emi_sens!$I$14:$I$21&"|"&Calculate_cap_emi_sens!$L$14:$L$21, Calculate_cap_emi_sens!$BE$14:$BE$21, "Not found", 0),"Rb",_xlfn.XLOOKUP(E3&"|"&B3, Calculate_cap_emi_sens!$I$14:$I$21&"|"&Calculate_cap_emi_sens!$L$14:$L$21, Calculate_cap_emi_sens!$BG$14:$BG$21, "Not found", 0),"Rl",_xlfn.XLOOKUP(E3&"|"&B3, Calculate_cap_emi_sens!$I$14:$I$21&"|"&Calculate_cap_emi_sens!$L$14:$L$21, Calculate_cap_emi_sens!$BH$14:$BH$21, "Not found", 0),"HP",_xlfn.XLOOKUP(E3&"|"&B3, Calculate_cap_emi_sens!$I$14:$I$21&"|"&Calculate_cap_emi_sens!$L$14:$L$21, Calculate_cap_emi_sens!$BF$14:$BF$21, "Not found", 0),"HPl",_xlfn.XLOOKUP(E3&"|"&B3, Calculate_cap_emi_sens!$I$14:$I$21&"|"&Calculate_cap_emi_sens!$L$14:$L$21, Calculate_cap_emi_sens!$BI$14:$BI$21, "Not found", 0),"Missing")} -> 0 | W3: =Results_proc_ener!L3 -> 24893.256 | X3: =Results_proc_ener!M3 -> 0 | Y3: =Results_proc_ener!N3 -> 0 | Z3: =Results_proc_ener!O3 -> 0 | AA3: =Results_proc_ener!P3 -> 0 | AB3: =Results_proc_ener!Q3 -> 982.85692 | AC3: =Results_proc_ener!R3 -> 17.878346 | AD3: =Results_proc_ener!S3 -> 101.62591 | AE3: =Results_proc_ener!T3 -> 0
A4: Mass-H1-Real | B4: =_xlfn.TEXTBEFORE(A4, "-", 2) -> Mass-H1 | C4: =_xlfn.TEXTBEFORE(A4, "-", 1) -> Mass | D4: =_xlfn.TEXTAFTER(B4, "-", 1) -> H1 | E4: AK | F4: R | I4: {=_xlfn.SWITCH(F4,"R",_xlfn.XLOOKUP(E4&"|"&B4, Calculate_cap_emi!$I$14:$I$21&"|"&Calculate_cap_emi!$L$14:$L$21, Calculate_cap_emi!$W$14:$W$21, "Not found", 0),"Rb",_xlfn.XLOOKUP(E4&"|"&B4, Calculate_cap_emi!$I$14:$I$21&"|"&Calculate_cap_emi!$L$14:$L$21, Calculate_cap_emi!$Y$14:$Y$21, "Not found", 0),"Rl",_xlfn.XLOOKUP(E4&"|"&B4, Calculate_cap_emi!$I$14:$I$21&"|"&Calculate_cap_emi!$L$14:$L$21, Calculate_cap_emi!$Z$14:$Z$21, "Not found", 0),0)} -> 7 | L4: {=_xlfn.SWITCH(F4,"R",_xlfn.XLOOKUP(E4&"|"&B4, Calculate_cap_emi!$I$14:$I$21&"|"&Calculate_cap_emi!$L$14:$L$21, Calculate_cap_emi!$AC$14:$AC$21, "Not found", 0),"Rb",_xlfn.XLOOKUP(E4&"|"&B4, Calculate_cap_emi!$I$14:$I$21&"|"&Calculate_cap_emi!$L$14:$L$21, Calculate_cap_emi!$AE$14:$AE$21, "Not found", 0),"Rl",_xlfn.XLOOKUP(E4&"|"&B4, Calculate_cap_emi!$I$14:$I$21&"|"&Calculate_cap_emi!$L$14:$L$21, Calculate_cap_emi!$AF$14:$AF$21, "Not found", 0),"HP",_xlfn.XLOOKUP(E4&"|"&B4, Calculate_cap_emi!$I$14:$I$21&"|"&Calculate_cap_emi!$L$14:$L$21, Calculate_cap_emi!$AD$14:$AD$21, "Not found", 0),"HPl",_xlfn.XLOOKUP(E4&"|"&B4, Calculate_cap_emi!$I$14:$I$21&"|"&Calculate_cap_emi!$L$14:$L$21, Calculate_cap_emi!$AG$14:$AG$21, "Not found", 0),"Missing")} -> 762.75655 | Q4: {=_xlfn.SWITCH(F4,"R",_xlfn.XLOOKUP(E4&"|"&B4, Calculate_cap_emi!$I$14:$I$21&"|"&Calculate_cap_emi!$L$14:$L$21, Calculate_cap_emi!$AJ$14:$AJ$21, "Not found", 0),"Rb",_xlfn.XLOOKUP(E4&"|"&B4, Calculate_cap_emi!$I$14:$I$21&"|"&Calculate_cap_emi!$L$14:$L$21, Calculate_cap_emi!$AL$14:$AL$21, "Not found", 0),"Rl",_xlfn.XLOOKUP(E4&"|"&B4, Calculate_cap_emi!$I$14:$I$21&"|"&Calculate_cap_emi!$L$14:$L$21, Calculate_cap_emi!$AM$14:$AM$21, "Not found", 0),"HP",_xlfn.XLOOKUP(E4&"|"&B4, Calculate_cap_emi!$I$14:$I$21&"|"&Calculate_cap_emi!$L$14:$L$21, Calculate_cap_emi!$AK$14:$AK$21, "Not found", 0),"HPl",_xlfn.XLOOKUP(E4&"|"&B4, Calculate_cap_emi!$I$14:$I$21&"|"&Calculate_cap_emi!$L$14:$L$21, Calculate_cap_emi!$AN$14:$AN$21, "Not found", 0),"Missing")} -> 34.392677 | R4: {=_xlfn.SWITCH(F4,"R",_xlfn.XLOOKUP(E4&"|"&B4, Calculate_cap_emi!$I$14:$I$21&"|"&Calculate_cap_emi!$L$14:$L$21, Calculate_cap_emi!$AQ$14:$AQ$21, "Not found", 0),"Rb",_xlfn.XLOOKUP(E4&"|"&B4, Calculate_cap_emi!$I$14:$I$21&"|"&Calculate_cap_emi!$L$14:$L$21, Calculate_cap_emi!$AS$14:$AS$21, "Not found", 0),"Rl",_xlfn.XLOOKUP(E4&"|"&B4, Calculate_cap_emi!$I$14:$I$21&"|"&Calculate_cap_emi!$L$14:$L$21, Calculate_cap_emi!$AT$14:$AT$21, "Not found", 0),"HP",_xlfn.XLOOKUP(E4&"|"&B4, Calculate_cap_emi!$I$14:$I$21&"|"&Calculate_cap_emi!$L$14:$L$21, Calculate_cap_emi!$AR$14:$AR$21, "Not found", 0),"HPl",_xlfn.XLOOKUP(E4&"|"&B4, Calculate_cap_emi!$I$14:$I$21&"|"&Calculate_cap_emi!$L$14:$L$21, Calculate_cap_emi!$AU$14:$AU$21, "Not found", 0),"Missing")} -> 4.2216804 | S4: {=_xlfn.SWITCH(F4,"R",_xlfn.XLOOKUP(E4&"|"&B4, Calculate_cap_emi!$I$14:$I$21&"|"&Calculate_cap_emi!$L$14:$L$21, Calculate_cap_emi!$AX$14:$AX$21, "Not found", 0),"Rb",_xlfn.XLOOKUP(E4&"|"&B4, Calculate_cap_emi!$I$14:$I$21&"|"&Calculate_cap_emi!$L$14:$L$21, Calculate_cap_emi!$AZ$14:$AZ$21, "Not found", 0),"Rl",_xlfn.XLOOKUP(E4&"|"&B4, Calculate_cap_emi!$I$14:$I$21&"|"&Calculate_cap_emi!$L$14:$L$21, Calculate_cap_emi!$BA$14:$BA$21, "Not found", 0),"HP",_xlfn.XLOOKUP(E4&"|"&B4, Calculate_cap_emi!$I$14:$I$21&"|"&Calculate_cap_emi!$L$14:$L$21, Calculate_cap_emi!$AY$14:$AY$21, "Not found", 0),"HPl",_xlfn.XLOOKUP(E4&"|"&B4, Calculate_cap_emi!$I$14:$I$21&"|"&Calculate_cap_emi!$L$14:$L$21, Calculate_cap_emi!$BB$14:$BB$21, "Not found", 0),"Missing")} -> 40.801369 | T4: {=_xlfn.SWITCH(F4,"R",_xlfn.XLOOKUP(E4&"|"&B4, Calculate_cap_emi!$I$14:$I$21&"|"&Calculate_cap_emi!$L$14:$L$21, Calculate_cap_emi!$BE$14:$BE$21, "Not found", 0),"Rb",_xlfn.XLOOKUP(E4&"|"&B4, Calculate_cap_emi!$I$14:$I$21&"|"&Calculate_cap_emi!$L$14:$L$21, Calculate_cap_emi!$BG$14:$BG$21, "Not found", 0),"Rl",_xlfn.XLOOKUP(E4&"|"&B4, Calculate_cap_emi!$I$14:$I$21&"|"&Calculate_cap_emi!$L$14:$L$21, Calculate_cap_emi!$BH$14:$BH$21, "Not found", 0),"HP",_xlfn.XLOOKUP(E4&"|"&B4, Calculate_cap_emi!$I$14:$I$21&"|"&Calculate_cap_emi!$L$14:$L$21, Calculate_cap_emi!$BF$14:$BF$21, "Not found", 0),"HPl",_xlfn.XLOOKUP(E4&"|"&B4, Calculate_cap_emi!$I$14:$I$21&"|"&Calculate_cap_emi!$L$14:$L$21, Calculate_cap_emi!$BI$14:$BI$21, "Not found", 0),"Missing")} -> 0 | U4: {=_xlfn.SWITCH(F4,"R",_xlfn.XLOOKUP(E4&"|"&B4, Calculate_cap_emi_sens!$I$14:$I$21&"|"&Calculate_cap_emi_sens!$L$14:$L$21, Calculate_cap_emi_sens!$AX$14:$AX$21, "Not found", 0),"Rb",_xlfn.XLOOKUP(E4&"|"&B4, Calculate_cap_emi_sens!$I$14:$I$21&"|"&Calculate_cap_emi_sens!$L$14:$L$21, Calculate_cap_emi_sens!$AZ$14:$AZ$21, "Not found", 0),"Rl",_xlfn.XLOOKUP(E4&"|"&B4, Calculate_cap_emi_sens!$I$14:$I$21&"|"&Calculate_cap_emi_sens!$L$14:$L$21, Calculate_cap_emi_sens!$BA$14:$BA$21, "Not found", 0),"HP",_xlfn.XLOOKUP(E4&"|"&B4, Calculate_cap_emi_sens!$I$14:$I$21&"|"&Calculate_cap_emi_sens!$L$14:$L$21, Calculate_cap_emi_sens!$AY$14:$AY$21, "Not found", 0),"HPl",_xlfn.XLOOKUP(E4&"|"&B4, Calculate_cap_emi_sens!$I$14:$I$21&"|"&Calculate_cap_emi_sens!$L$14:$L$21, Calculate_cap_emi_sens!$BB$14:$BB$21, "Not found", 0),"Missing")} -> 40.801369 | V4: {=_xlfn.SWITCH(F4,"R",_xlfn.XLOOKUP(E4&"|"&B4, Calculate_cap_emi_sens!$I$14:$I$21&"|"&Calculate_cap_emi_sens!$L$14:$L$21, Calculate_cap_emi_sens!$BE$14:$BE$21, "Not found", 0),"Rb",_xlfn.XLOOKUP(E4&"|"&B4, Calculate_cap_emi_sens!$I$14:$I$21&"|"&Calculate_cap_emi_sens!$L$14:$L$21, Calculate_cap_emi_sens!$BG$14:$BG$21, "Not found", 0),"Rl",_xlfn.XLOOKUP(E4&"|"&B4, Calculate_cap_emi_sens!$I$14:$I$21&"|"&Calculate_cap_emi_sens!$L$14:$L$21, Calculate_cap_emi_sens!$BH$14:$BH$21, "Not found", 0),"HP",_xlfn.XLOOKUP(E4&"|"&B4, Calculate_cap_emi_sens!$I$14:$I$21&"|"&Calculate_cap_emi_sens!$L$14:$L$21, Calculate_cap_emi_sens!$BF$14:$BF$21, "Not found", 0),"HPl",_xlfn.XLOOKUP(E4&"|"&B4, Calculate_cap_emi_sens!$I$14:$I$21&"|"&Calculate_cap_emi_sens!$L$14:$L$21, Calculate_cap_emi_sens!$BI$14:$BI$21, "Not found", 0),"Missing")} -> 0 | W4: =Results_proc_ener!L4 -> 19975.71 | X4: =Results_proc_ener!M4 -> 0 | Y4: =Results_proc_ener!N4 -> 0 | Z4: =Results_proc_ener!O4 -> 0 | AA4: =Results_proc_ener!P4 -> 0 | AB4: =Results_proc_ener!Q4 -> 728.39025 | AC4: =Results_proc_ener!R4 -> 14.55723 | AD4: =Results_proc_ener!S4 -> 86.552477 | AE4: =Results_proc_ener!T4 -> 0
A5: Mass-H1-Ideal | B5: =_xlfn.TEXTBEFORE(A5, "-", 2) -> Mass-H1 | C5: =_xlfn.TEXTBEFORE(A5, "-", 1) -> Mass | D5: =_xlfn.TEXTAFTER(B5, "-", 1) -> H1 | E5: AK | F5: R | I5: {=_xlfn.SWITCH(F5,"R",_xlfn.XLOOKUP(E5&"|"&B5, Calculate_cap_emi!$I$14:$I$21&"|"&Calculate_cap_emi!$L$14:$L$21, Calculate_cap_emi!$W$14:$W$21, "Not found", 0),"Rb",_xlfn.XLOOKUP(E5&"|"&B5, Calculate_cap_emi!$I$14:$I$21&"|"&Calculate_cap_emi!$L$14:$L$21, Calculate_cap_emi!$Y$14:$Y$21, "Not found", 0),"Rl",_xlfn.XLOOKUP(E5&"|"&B5, Calculate_cap_emi!$I$14:$I$21&"|"&Calculate_cap_emi!$L$14:$L$21, Calculate_cap_emi!$Z$14:$Z$21, "Not found", 0),0)} -> 7 | L5: {=_xlfn.SWITCH(F5,"R",_xlfn.XLOOKUP(E5&"|"&B5, Calculate_cap_emi!$I$14:$I$21&"|"&Calculate_cap_emi!$L$14:$L$21, Calculate_cap_emi!$AC$14:$AC$21, "Not found", 0),"Rb",_xlfn.XLOOKUP(E5&"|"&B5, Calculate_cap_emi!$I$14:$I$21&"|"&Calculate_cap_emi!$L$14:$L$21, Calculate_cap_emi!$AE$14:$AE$21, "Not found", 0),"Rl",_xlfn.XLOOKUP(E5&"|"&B5, Calculate_cap_emi!$I$14:$I$21&"|"&Calculate_cap_emi!$L$14:$L$21, Calculate_cap_emi!$AF$14:$AF$21, "Not found", 0),"HP",_xlfn.XLOOKUP(E5&"|"&B5, Calculate_cap_emi!$I$14:$I$21&"|"&Calculate_cap_emi!$L$14:$L$21, Calculate_cap_emi!$AD$14:$AD$21, "Not found", 0),"HPl",_xlfn.XLOOKUP(E5&"|"&B5, Calculate_cap_emi!$I$14:$I$21&"|"&Calculate_cap_emi!$L$14:$L$21, Calculate_cap_emi!$AG$14:$AG$21, "Not found", 0),"Missing")} -> 762.75655 | Q5: {=_xlfn.SWITCH(F5,"R",_xlfn.XLOOKUP(E5&"|"&B5, Calculate_cap_emi!$I$14:$I$21&"|"&Calculate_cap_emi!$L$14:$L$21, Calculate_cap_emi!$AJ$14:$AJ$21, "Not found", 0),"Rb",_xlfn.XLOOKUP(E5&"|"&B5, Calculate_cap_emi!$I$14:$I$21&"|"&Calculate_cap_emi!$L$14:$L$21, Calculate_cap_emi!$AL$14:$AL$21, "Not found", 0),"Rl",_xlfn.XLOOKUP(E5&"|"&B5, Calculate_cap_emi!$I$14:$I$21&"|"&Calculate_cap_emi!$L$14:$L$21, Calculate_cap_emi!$AM$14:$AM$21, "Not found", 0),"HP",_xlfn.XLOOKUP(E5&"|"&B5, Calculate_cap_emi!$I$14:$I$21&"|"&Calculate_cap_emi!$L$14:$L$21, Calculate_cap_emi!$AK$14:$AK$21, "Not found", 0),"HPl",_xlfn.XLOOKUP(E5&"|"&B5, Calculate_cap_emi!$I$14:$I$21&"|"&Calculate_cap_emi!$L$14:$L$21, Calculate_cap_emi!$AN$14:$AN$21, "Not found", 0),"Missing")} -> 34.392677 | R5: {=_xlfn.SWITCH(F5,"R",_xlfn.XLOOKUP(E5&"|"&B5, Calculate_cap_emi!$I$14:$I$21&"|"&Calculate_cap_emi!$L$14:$L$21, Calculate_cap_emi!$AQ$14:$AQ$21, "Not found", 0),"Rb",_xlfn.XLOOKUP(E5&"|"&B5, Calculate_cap_emi!$I$14:$I$21&"|"&Calculate_cap_emi!$L$14:$L$21, Calculate_cap_emi!$AS$14:$AS$21, "Not found", 0),"Rl",_xlfn.XLOOKUP(E5&"|"&B5, Calculate_cap_emi!$I$14:$I$21&"|"&Calculate_cap_emi!$L$14:$L$21, Calculate_cap_emi!$AT$14:$AT$21, "Not found", 0),"HP",_xlfn.XLOOKUP(E5&"|"&B5, Calculate_cap_emi!$I$14:$I$21&"|"&Calculate_cap_emi!$L$14:$L$21, Calculate_cap_emi!$AR$14:$AR$21, "Not found", 0),"HPl",_xlfn.XLOOKUP(E5&"|"&B5, Calculate_cap_emi!$I$14:$I$21&"|"&Calculate_cap_emi!$L$14:$L$21, Calculate_cap_emi!$AU$14:$AU$21, "Not found", 0),"Missing")} -> 4.2216804 | S5: {=_xlfn.SWITCH(F5,"R",_xlfn.XLOOKUP(E5&"|"&B5, Calculate_cap_emi!$I$14:$I$21&"|"&Calculate_cap_emi!$L$14:$L$21, Calculate_cap_emi!$AX$14:$AX$21, "Not found", 0),"Rb",_xlfn.XLOOKUP(E5&"|"&B5, Calculate_cap_emi!$I$14:$I$21&"|"&Calculate_cap_emi!$L$14:$L$21, Calculate_cap_emi!$AZ$14:$AZ$21, "Not found", 0),"Rl",_xlfn.XLOOKUP(E5&"|"&B5, Calculate_cap_emi!$I$14:$I$21&"|"&Calculate_cap_emi!$L$14:$L$21, Calculate_cap_emi!$BA$14:$BA$21, "Not found", 0),"HP",_xlfn.XLOOKUP(E5&"|"&B5, Calculate_cap_emi!$I$14:$I$21&"|"&Calculate_cap_emi!$L$14:$L$21, Calculate_cap_emi!$AY$14:$AY$21, "Not found", 0),"HPl",_xlfn.XLOOKUP(E5&"|"&B5, Calculate_cap_emi!$I$14:$I$21&"|"&Calculate_cap_emi!$L$14:$L$21, Calculate_cap_emi!$BB$14:$BB$21, "Not found", 0),"Missing")} -> 40.801369 | T5: {=_xlfn.SWITCH(F5,"R",_xlfn.XLOOKUP(E5&"|"&B5, Calculate_cap_emi!$I$14:$I$21&"|"&Calculate_cap_emi!$L$14:$L$21, Calculate_cap_emi!$BE$14:$BE$21, "Not found", 0),"Rb",_xlfn.XLOOKUP(E5&"|"&B5, Calculate_cap_emi!$I$14:$I$21&"|"&Calculate_cap_emi!$L$14:$L$21, Calculate_cap_emi!$BG$14:$BG$21, "Not found", 0),"Rl",_xlfn.XLOOKUP(E5&"|"&B5, Calculate_cap_emi!$I$14:$I$21&"|"&Calculate_cap_emi!$L$14:$L$21, Calculate_cap_emi!$BH$14:$BH$21, "Not found", 0),"HP",_xlfn.XLOOKUP(E5&"|"&B5, Calculate_cap_emi!$I$14:$I$21&"|"&Calculate_cap_emi!$L$14:$L$21, Calculate_cap_emi!$BF$14:$BF$21, "Not found", 0),"HPl",_xlfn.XLOOKUP(E5&"|"&B5, Calculate_cap_emi!$I$14:$I$21&"|"&Calculate_cap_emi!$L$14:$L$21, Calculate_cap_emi!$BI$14:$BI$21, "Not found", 0),"Missing")} -> 0 | U5: {=_xlfn.SWITCH(F5,"R",_xlfn.XLOOKUP(E5&"|"&B5, Calculate_cap_emi_sens!$I$14:$I$21&"|"&Calculate_cap_emi_sens!$L$14:$L$21, Calculate_cap_emi_sens!$AX$14:$AX$21, "Not found", 0),"Rb",_xlfn.XLOOKUP(E5&"|"&B5, Calculate_cap_emi_sens!$I$14:$I$21&"|"&Calculate_cap_emi_sens!$L$14:$L$21, Calculate_cap_emi_sens!$AZ$14:$AZ$21, "Not found", 0),"Rl",_xlfn.XLOOKUP(E5&"|"&B5, Calculate_cap_emi_sens!$I$14:$I$21&"|"&Calculate_cap_emi_sens!$L$14:$L$21, Calculate_cap_emi_sens!$BA$14:$BA$21, "Not found", 0),"HP",_xlfn.XLOOKUP(E5&"|"&B5, Calculate_cap_emi_sens!$I$14:$I$21&"|"&Calculate_cap_emi_sens!$L$14:$L$21, Calculate_cap_emi_sens!$AY$14:$AY$21, "Not found", 0),"HPl",_xlfn.XLOOKUP(E5&"|"&B5, Calculate_cap_emi_sens!$I$14:$I$21&"|"&Calculate_cap_emi_sens!$L$14:$L$21, Calculate_cap_emi_sens!$BB$14:$BB$21, "Not found", 0),"Missing")} -> 40.801369 | V5: {=_xlfn.SWITCH(F5,"R",_xlfn.XLOOKUP(E5&"|"&B5, Calculate_cap_emi_sens!$I$14:$I$21&"|"&Calculate_cap_emi_sens!$L$14:$L$21, Calculate_cap_emi_sens!$BE$14:$BE$21, "Not found", 0),"Rb",_xlfn.XLOOKUP(E5&"|"&B5, Calculate_cap_emi_sens!$I$14:$I$21&"|"&Calculate_cap_emi_sens!$L$14:$L$21, Calculate_cap_emi_sens!$BG$14:$BG$21, "Not found", 0),"Rl",_xlfn.XLOOKUP(E5&"|"&B5, Calculate_cap_emi_sens!$I$14:$I$21&"|"&Calculate_cap_emi_sens!$L$14:$L$21, Calculate_cap_emi_sens!$BH$14:$BH$21, "Not found", 0),"HP",_xlfn.XLOOKUP(E5&"|"&B5, Calculate_cap_emi_sens!$I$14:$I$21&"|"&Calculate_cap_emi_sens!$L$14:$L$21, Calculate_cap_emi_sens!$BF$14:$BF$21, "Not found", 0),"HPl",_xlfn.XLOOKUP(E5&"|"&B5, Calculate_cap_emi_sens!$I$14:$I$21&"|"&Calculate_cap_emi_sens!$L$14:$L$21, Calculate_cap_emi_sens!$BI$14:$BI$21, "Not found", 0),"Missing")} -> 0 | W5: =Results_proc_ener!L5 -> 19975.71 | X5: =Results_proc_ener!M5 -> 0 | Y5: =Results_proc_ener!N5 -> 0 | Z5: =Results_proc_ener!O5 -> 0 | AA5: =Results_proc_ener!P5 -> 0 | AB5: =Results_proc_ener!Q5 -> 728.39025 | AC5: =Results_proc_ener!R5 -> 14.55723 | AD5: =Results_proc_ener!S5 -> 86.552477 | AE5: =Results_proc_ener!T5 -> 0
A6: Mod-Nom-Real | B6: =_xlfn.TEXTBEFORE(A6, "-", 2) -> Mod-Nom | C6: =_xlfn.TEXTBEFORE(A6, "-", 1) -> Mod | D6: =_xlfn.TEXTAFTER(B6, "-", 1) -> Nom | E6: AK | F6: R | I6: {=_xlfn.SWITCH(F6,"R",_xlfn.XLOOKUP(E6&"|"&B6, Calculate_cap_emi!$I$14:$I$21&"|"&Calculate_cap_emi!$L$14:$L$21, Calculate_cap_emi!$W$14:$W$21, "Not found", 0),"Rb",_xlfn.XLOOKUP(E6&"|"&B6, Calculate_cap_emi!$I$14:$I$21&"|"&Calculate_cap_emi!$L$14:$L$21, Calculate_cap_emi!$Y$14:$Y$21, "Not found", 0),"Rl",_xlfn.XLOOKUP(E6&"|"&B6, Calculate_cap_emi!$I$14:$I$21&"|"&Calculate_cap_emi!$L$14:$L$21, Calculate_cap_emi!$Z$14:$Z$21, "Not found", 0),0)} -> 12 | L6: {=_xlfn.SWITCH(F6,"R",_xlfn.XLOOKUP(E6&"|"&B6, Calculate_cap_emi!$I$14:$I$21&"|"&Calculate_cap_emi!$L$14:$L$21, Calculate_cap_emi!$AC$14:$AC$21, "Not found", 0),"Rb",_xlfn.XLOOKUP(E6&"|"&B6, Calculate_cap_emi!$I$14:$I$21&"|"&Calculate_cap_emi!$L$14:$L$21, Calculate_cap_emi!$AE$14:$AE$21, "Not found", 0),"Rl",_xlfn.XLOOKUP(E6&"|"&B6, Calculate_cap_emi!$I$14:$I$21&"|"&Calculate_cap_emi!$L$14:$L$21, Calculate_cap_emi!$AF$14:$AF$21, "Not found", 0),"HP",_xlfn.XLOOKUP(E6&"|"&B6, Calculate_cap_emi!$I$14:$I$21&"|"&Calculate_cap_emi!$L$14:$L$21, Calculate_cap_emi!$AD$14:$AD$21, "Not found", 0),"HPl",_xlfn.XLOOKUP(E6&"|"&B6, Calculate_cap_emi!$I$14:$I$21&"|"&Calculate_cap_emi!$L$14:$L$21, Calculate_cap_emi!$AG$14:$AG$21, "Not found", 0),"Missing")} -> 1286.5077 | Q6: {=_xlfn.SWITCH(F6,"R",_xlfn.XLOOKUP(E6&"|"&B6, Calculate_cap_emi!$I$14:$I$21&"|"&Calculate_cap_emi!$L$14:$L$21, Calculate_cap_emi!$AJ$14:$AJ$21, "Not found", 0),"Rb",_xlfn.XLOOKUP(E6&"|"&B6, Calculate_cap_emi!$I$14:$I$21&"|"&Calculate_cap_emi!$L$14:$L$21, Calculate_cap_emi!$AL$14:$AL$21, "Not found", 0),"Rl",_xlfn.XLOOKUP(E6&"|"&B6, Calculate_cap_emi!$I$14:$I$21&"|"&Calculate_cap_emi!$L$14:$L$21, Calculate_cap_emi!$AM$14:$AM$21, "Not found", 0),"HP",_xlfn.XLOOKUP(E6&"|"&B6, Calculate_cap_emi!$I$14:$I$21&"|"&Calculate_cap_emi!$L$14:$L$21, Calculate_cap_emi!$AK$14:$AK$21, "Not found", 0),"HPl",_xlfn.XLOOKUP(E6&"|"&B6, Calculate_cap_emi!$I$14:$I$21&"|"&Calculate_cap_emi!$L$14:$L$21, Calculate_cap_emi!$AN$14:$AN$21, "Not found", 0),"Missing")} -> 58.322398 | R6: {=_xlfn.SWITCH(F6,"R",_xlfn.XLOOKUP(E6&"|"&B6, Calculate_cap_emi!$I$14:$I$21&"|"&Calculate_cap_emi!$L$14:$L$21, Calculate_cap_emi!$AQ$14:$AQ$21, "Not found", 0),"Rb",_xlfn.XLOOKUP(E6&"|"&B6, Calculate_cap_emi!$I$14:$I$21&"|"&Calculate_cap_emi!$L$14:$L$21, Calculate_cap_emi!$AS$14:$AS$21, "Not found", 0),"Rl",_xlfn.XLOOKUP(E6&"|"&B6, Calculate_cap_emi!$I$14:$I$21&"|"&Calculate_cap_emi!$L$14:$L$21, Calculate_cap_emi!$AT$14:$AT$21, "Not found", 0),"HP",_xlfn.XLOOKUP(E6&"|"&B6, Calculate_cap_emi!$I$14:$I$21&"|"&Calculate_cap_emi!$L$14:$L$21, Calculate_cap_emi!$AR$14:$AR$21, "Not found", 0),"HPl",_xlfn.XLOOKUP(E6&"|"&B6, Calculate_cap_emi!$I$14:$I$21&"|"&Calculate_cap_emi!$L$14:$L$21, Calculate_cap_emi!$AU$14:$AU$21, "Not found", 0),"Missing")} -> 7.0757825 | S6: {=_xlfn.SWITCH(F6,"R",_xlfn.XLOOKUP(E6&"|"&B6, Calculate_cap_emi!$I$14:$I$21&"|"&Calculate_cap_emi!$L$14:$L$21, Calculate_cap_emi!$AX$14:$AX$21, "Not found", 0),"Rb",_xlfn.XLOOKUP(E6&"|"&B6, Calculate_cap_emi!$I$14:$I$21&"|"&Calculate_cap_emi!$L$14:$L$21, Calculate_cap_emi!$AZ$14:$AZ$21, "Not found", 0),"Rl",_xlfn.XLOOKUP(E6&"|"&B6, Calculate_cap_emi!$I$14:$I$21&"|"&Calculate_cap_emi!$L$14:$L$21, Calculate_cap_emi!$BA$14:$BA$21, "Not found", 0),"HP",_xlfn.XLOOKUP(E6&"|"&B6, Calculate_cap_emi!$I$14:$I$21&"|"&Calculate_cap_emi!$L$14:$L$21, Calculate_cap_emi!$AY$14:$AY$21, "Not found", 0),"HPl",_xlfn.XLOOKUP(E6&"|"&B6, Calculate_cap_emi!$I$14:$I$21&"|"&Calculate_cap_emi!$L$14:$L$21, Calculate_cap_emi!$BB$14:$BB$21, "Not found", 0),"Missing")} -> 69.179087 | T6: {=_xlfn.SWITCH(F6,"R",_xlfn.XLOOKUP(E6&"|"&B6, Calculate_cap_emi!$I$14:$I$21&"|"&Calculate_cap_emi!$L$14:$L$21, Calculate_cap_emi!$BE$14:$BE$21, "Not found", 0),"Rb",_xlfn.XLOOKUP(E6&"|"&B6, Calculate_cap_emi!$I$14:$I$21&"|"&Calculate_cap_emi!$L$14:$L$21, Calculate_cap_emi!$BG$14:$BG$21, "Not found", 0),"Rl",_xlfn.XLOOKUP(E6&"|"&B6, Calculate_cap_emi!$I$14:$I$21&"|"&Calculate_cap_emi!$L$14:$L$21, Calculate_cap_emi!$BH$14:$BH$21, "Not found", 0),"HP",_xlfn.XLOOKUP(E6&"|"&B6, Calculate_cap_emi!$I$14:$I$21&"|"&Calculate_cap_emi!$L$14:$L$21, Calculate_cap_emi!$BF$14:$BF$21, "Not found", 0),"HPl",_xlfn.XLOOKUP(E6&"|"&B6, Calculate_cap_emi!$I$14:$I$21&"|"&Calculate_cap_emi!$L$14:$L$21, Calculate_cap_emi!$BI$14:$BI$21, "Not found", 0),"Missing")} -> 0 | U6: {=_xlfn.SWITCH(F6,"R",_xlfn.XLOOKUP(E6&"|"&B6, Calculate_cap_emi_sens!$I$14:$I$21&"|"&Calculate_cap_emi_sens!$L$14:$L$21, Calculate_cap_emi_sens!$AX$14:$AX$21, "Not found", 0),"Rb",_xlfn.XLOOKUP(E6&"|"&B6, Calculate_cap_emi_sens!$I$14:$I$21&"|"&Calculate_cap_emi_sens!$L$14:$L$21, Calculate_cap_emi_sens!$AZ$14:$AZ$21, "Not found", 0),"Rl",_xlfn.XLOOKUP(E6&"|"&B6, Calculate_cap_emi_sens!$I$14:$I$21&"|"&Calculate_cap_emi_sens!$L$14:$L$21, Calculate_cap_emi_sens!$BA$14:$BA$21, "Not found", 0),"HP",_xlfn.XLOOKUP(E6&"|"&B6, Calculate_cap_emi_sens!$I$14:$I$21&"|"&Calculate_cap_emi_sens!$L$14:$L$21, Calculate_cap_emi_sens!$AY$14:$AY$21, "Not found", 0),"HPl",_xlfn.XLOOKUP(E6&"|"&B6, Calculate_cap_emi_sens!$I$14:$I$21&"|"&Calculate_cap_emi_sens!$L$14:$L$21, Calculate_cap_emi_sens!$BB$14:$BB$21, "Not found", 0),"Missing")} -> 69.179087 | V6: {=_xlfn.SWITCH(F6,"R",_xlfn.XLOOKUP(E6&"|"&B6, Calculate_cap_emi_sens!$I$14:$I$21&"|"&Calculate_cap_emi_sens!$L$14:$L$21, Calculate_cap_emi_sens!$BE$14:$BE$21, "Not found", 0),"Rb",_xlfn.XLOOKUP(E6&"|"&B6, Calculate_cap_emi_sens!$I$14:$I$21&"|"&Calculate_cap_emi_sens!$L$14:$L$21, Calculate_cap_emi_sens!$BG$14:$BG$21, "Not found", 0),"Rl",_xlfn.XLOOKUP(E6&"|"&B6, Calculate_cap_emi_sens!$I$14:$I$21&"|"&Calculate_cap_emi_sens!$L$14:$L$21, Calculate_cap_emi_sens!$BH$14:$BH$21, "Not found", 0),"HP",_xlfn.XLOOKUP(E6&"|"&B6, Calculate_cap_emi_sens!$I$14:$I$21&"|"&Calculate_cap_emi_sens!$L$14:$L$21, Calculate_cap_emi_sens!$BF$14:$BF$21, "Not found", 0),"HPl",_xlfn.XLOOKUP(E6&"|"&B6, Calculate_cap_emi_sens!$I$14:$I$21&"|"&Calculate_cap_emi_sens!$L$14:$L$21, Calculate_cap_emi_sens!$BI$14:$BI$21, "Not found", 0),"Missing")} -> 0 | W6: =Results_proc_ener!L6 -> 33702.645 | X6: =Results_proc_ener!M6 -> 0 | Y6: =Results_proc_ener!N6 -> 0 | Z6: =Results_proc_ener!O6 -> 0 | AA6: =Results_proc_ener!P6 -> 0 | AB6: =Results_proc_ener!Q6 -> 1235.1893 | AC6: =Results_proc_ener!R6 -> 24.53881 | AD6: =Results_proc_ener!S6 -> 145.51025 | AE6: =Results_proc_ener!T6 -> 0
A7: Mod-Nom-Ideal | B7: =_xlfn.TEXTBEFORE(A7, "-", 2) -> Mod-Nom | C7: =_xlfn.TEXTBEFORE(A7, "-", 1) -> Mod | D7: =_xlfn.TEXTAFTER(B7, "-", 1) -> Nom | E7: AK | F7: R | I7: {=_xlfn.SWITCH(F7,"R",_xlfn.XLOOKUP(E7&"|"&B7, Calculate_cap_emi!$I$14:$I$21&"|"&Calculate_cap_emi!$L$14:$L$21, Calculate_cap_emi!$W$14:$W$21, "Not found", 0),"Rb",_xlfn.XLOOKUP(E7&"|"&B7, Calculate_cap_emi!$I$14:$I$21&"|"&Calculate_cap_emi!$L$14:$L$21, Calculate_cap_emi!$Y$14:$Y$21, "Not found", 0),"Rl",_xlfn.XLOOKUP(E7&"|"&B7, Calculate_cap_emi!$I$14:$I$21&"|"&Calculate_cap_emi!$L$14:$L$21, Calculate_cap_emi!$Z$14:$Z$21, "Not found", 0),0)} -> 12 | L7: {=_xlfn.SWITCH(F7,"R",_xlfn.XLOOKUP(E7&"|"&B7, Calculate_cap_emi!$I$14:$I$21&"|"&Calculate_cap_emi!$L$14:$L$21, Calculate_cap_emi!$AC$14:$AC$21, "Not found", 0),"Rb",_xlfn.XLOOKUP(E7&"|"&B7, Calculate_cap_emi!$I$14:$I$21&"|"&Calculate_cap_emi!$L$14:$L$21, Calculate_cap_emi!$AE$14:$AE$21, "Not found", 0),"Rl",_xlfn.XLOOKUP(E7&"|"&B7, Calculate_cap_emi!$I$14:$I$21&"|"&Calculate_cap_emi!$L$14:$L$21, Calculate_cap_emi!$AF$14:$AF$21, "Not found", 0),"HP",_xlfn.XLOOKUP(E7&"|"&B7, Calculate_cap_emi!$I$14:$I$21&"|"&Calculate_cap_emi!$L$14:$L$21, Calculate_cap_emi!$AD$14:$AD$21, "Not found", 0),"HPl",_xlfn.XLOOKUP(E7&"|"&B7, Calculate_cap_emi!$I$14:$I$21&"|"&Calculate_cap_emi!$L$14:$L$21, Calculate_cap_emi!$AG$14:$AG$21, "Not found", 0),"Missing")} -> 1286.5077 | Q7: {=_xlfn.SWITCH(F7,"R",_xlfn.XLOOKUP(E7&"|"&B7, Calculate_cap_emi!$I$14:$I$21&"|"&Calculate_cap_emi!$L$14:$L$21, Calculate_cap_emi!$AJ$14:$AJ$21, "Not found", 0),"Rb",_xlfn.XLOOKUP(E7&"|"&B7, Calculate_cap_emi!$I$14:$I$21&"|"&Calculate_cap_emi!$L$14:$L$21, Calculate_cap_emi!$AL$14:$AL$21, "Not found", 0),"Rl",_xlfn.XLOOKUP(E7&"|"&B7, Calculate_cap_emi!$I$14:$I$21&"|"&Calculate_cap_emi!$L$14:$L$21, Calculate_cap_emi!$AM$14:$AM$21, "Not found", 0),"HP",_xlfn.XLOOKUP(E7&"|"&B7, Calculate_cap_emi!$I$14:$I$21&"|"&Calculate_cap_emi!$L$14:$L$21, Calculate_cap_emi!$AK$14:$AK$21, "Not found", 0),"HPl",_xlfn.XLOOKUP(E7&"|"&B7, Calculate_cap_emi!$I$14:$I$21&"|"&Calculate_cap_emi!$L$14:$L$21, Calculate_cap_emi!$AN$14:$AN$21, "Not found", 0),"Missing")} -> 58.322398 | R7: {=_xlfn.SWITCH(F7,"R",_xlfn.XLOOKUP(E7&"|"&B7, Calculate_cap_emi!$I$14:$I$21&"|"&Calculate_cap_emi!$L$14:$L$21, Calculate_cap_emi!$AQ$14:$AQ$21, "Not found", 0),"Rb",_xlfn.XLOOKUP(E7&"|"&B7, Calculate_cap_emi!$I$14:$I$21&"|"&Calculate_cap_emi!$L$14:$L$21, Calculate_cap_emi!$AS$14:$AS$21, "Not found", 0),"Rl",_xlfn.XLOOKUP(E7&"|"&B7, Calculate_cap_emi!$I$14:$I$21&"|"&Calculate_cap_emi!$L$14:$L$21, Calculate_cap_emi!$AT$14:$AT$21, "Not found", 0),"HP",_xlfn.XLOOKUP(E7&"|"&B7, Calculate_cap_emi!$I$14:$I$21&"|"&Calculate_cap_emi!$L$14:$L$21, Calculate_cap_emi!$AR$14:$AR$21, "Not found", 0),"HPl",_xlfn.XLOOKUP(E7&"|"&B7, Calculate_cap_emi!$I$14:$I$21&"|"&Calculate_cap_emi!$L$14:$L$21, Calculate_cap_emi!$AU$14:$AU$21, "Not found", 0),"Missing")} -> 7.0757825 | S7: {=_xlfn.SWITCH(F7,"R",_xlfn.XLOOKUP(E7&"|"&B7, Calculate_cap_emi!$I$14:$I$21&"|"&Calculate_cap_emi!$L$14:$L$21, Calculate_cap_emi!$AX$14:$AX$21, "Not found", 0),"Rb",_xlfn.XLOOKUP(E7&"|"&B7, Calculate_cap_emi!$I$14:$I$21&"|"&Calculate_cap_emi!$L$14:$L$21, Calculate_cap_emi!$AZ$14:$AZ$21, "Not found", 0),"Rl",_xlfn.XLOOKUP(E7&"|"&B7, Calculate_cap_emi!$I$14:$I$21&"|"&Calculate_cap_emi!$L$14:$L$21, Calculate_cap_emi!$BA$14:$BA$21, "Not found", 0),"HP",_xlfn.XLOOKUP(E7&"|"&B7, Calculate_cap_emi!$I$14:$I$21&"|"&Calculate_cap_emi!$L$14:$L$21, Calculate_cap_emi!$AY$14:$AY$21, "Not found", 0),"HPl",_xlfn.XLOOKUP(E7&"|"&B7, Calculate_cap_emi!$I$14:$I$21&"|"&Calculate_cap_emi!$L$14:$L$21, Calculate_cap_emi!$BB$14:$BB$21, "Not found", 0),"Missing")} -> 69.179087 | T7: {=_xlfn.SWITCH(F7,"R",_xlfn.XLOOKUP(E7&"|"&B7, Calculate_cap_emi!$I$14:$I$21&"|"&Calculate_cap_emi!$L$14:$L$21, Calculate_cap_emi!$BE$14:$BE$21, "Not found", 0),"Rb",_xlfn.XLOOKUP(E7&"|"&B7, Calculate_cap_emi!$I$14:$I$21&"|"&Calculate_cap_emi!$L$14:$L$21, Calculate_cap_emi!$BG$14:$BG$21, "Not found", 0),"Rl",_xlfn.XLOOKUP(E7&"|"&B7, Calculate_cap_emi!$I$14:$I$21&"|"&Calculate_cap_emi!$L$14:$L$21, Calculate_cap_emi!$BH$14:$BH$21, "Not found", 0),"HP",_xlfn.XLOOKUP(E7&"|"&B7, Calculate_cap_emi!$I$14:$I$21&"|"&Calculate_cap_emi!$L$14:$L$21, Calculate_cap_emi!$BF$14:$BF$21, "Not found", 0),"HPl",_xlfn.XLOOKUP(E7&"|"&B7, Calculate_cap_emi!$I$14:$I$21&"|"&Calculate_cap_emi!$L$14:$L$21, Calculate_cap_emi!$BI$14:$BI$21, "Not found", 0),"Missing")} -> 0 | U7: {=_xlfn.SWITCH(F7,"R",_xlfn.XLOOKUP(E7&"|"&B7, Calculate_cap_emi_sens!$I$14:$I$21&"|"&Calculate_cap_emi_sens!$L$14:$L$21, Calculate_cap_emi_sens!$AX$14:$AX$21, "Not found", 0),"Rb",_xlfn.XLOOKUP(E7&"|"&B7, Calculate_cap_emi_sens!$I$14:$I$21&"|"&Calculate_cap_emi_sens!$L$14:$L$21, Calculate_cap_emi_sens!$AZ$14:$AZ$21, "Not found", 0),"Rl",_xlfn.XLOOKUP(E7&"|"&B7, Calculate_cap_emi_sens!$I$14:$I$21&"|"&Calculate_cap_emi_sens!$L$14:$L$21, Calculate_cap_emi_sens!$BA$14:$BA$21, "Not found", 0),"HP",_xlfn.XLOOKUP(E7&"|"&B7, Calculate_cap_emi_sens!$I$14:$I$21&"|"&Calculate_cap_emi_sens!$L$14:$L$21, Calculate_cap_emi_sens!$AY$14:$AY$21, "Not found", 0),"HPl",_xlfn.XLOOKUP(E7&"|"&B7, Calculate_cap_emi_sens!$I$14:$I$21&"|"&Calculate_cap_emi_sens!$L$14:$L$21, Calculate_cap_emi_sens!$BB$14:$BB$21, "Not found", 0),"Missing")} -> 69.179087 | V7: {=_xlfn.SWITCH(F7,"R",_xlfn.XLOOKUP(E7&"|"&B7, Calculate_cap_emi_sens!$I$14:$I$21&"|"&Calculate_cap_emi_sens!$L$14:$L$21, Calculate_cap_emi_sens!$BE$14:$BE$21, "Not found", 0),"Rb",_xlfn.XLOOKUP(E7&"|"&B7, Calculate_cap_emi_sens!$I$14:$I$21&"|"&Calculate_cap_emi_sens!$L$14:$L$21, Calculate_cap_emi_sens!$BG$14:$BG$21, "Not found", 0),"Rl",_xlfn.XLOOKUP(E7&"|"&B7, Calculate_cap_emi_sens!$I$14:$I$21&"|"&Calculate_cap_emi_sens!$L$14:$L$21, Calculate_cap_emi_sens!$BH$14:$BH$21, "Not found", 0),"HP",_xlfn.XLOOKUP(E7&"|"&B7, Calculate_cap_emi_sens!$I$14:$I$21&"|"&Calculate_cap_emi_sens!$L$14:$L$21, Calculate_cap_emi_sens!$BF$14:$BF$21, "Not found", 0),"HPl",_xlfn.XLOOKUP(E7&"|"&B7, Calculate_cap_emi_sens!$I$14:$I$21&"|"&Calculate_cap_emi_sens!$L$14:$L$21, Calculate_cap_emi_sens!$BI$14:$BI$21, "Not found", 0),"Missing")} -> 0 | W7: =Results_proc_ener!L7 -> 33702.645 | X7: =Results_proc_ener!M7 -> 0 | Y7: =Results_proc_ener!N7 -> 0 | Z7: =Results_proc_ener!O7 -> 0 | AA7: =Results_proc_ener!P7 -> 0 | AB7: =Results_proc_ener!Q7 -> 1235.1893 | AC7: =Results_proc_ener!R7 -> 24.53881 | AD7: =Results_proc_ener!S7 -> 145.51025 | AE7: =Results_proc_ener!T7 -> 0
A8: Mod-H1-Real | B8: =_xlfn.TEXTBEFORE(A8, "-", 2) -> Mod-H1 | C8: =_xlfn.TEXTBEFORE(A8, "-", 1) -> Mod | D8: =_xlfn.TEXTAFTER(B8, "-", 1) -> H1 | E8: AK | F8: R | I8: {=_xlfn.SWITCH(F8,"R",_xlfn.XLOOKUP(E8&"|"&B8, Calculate_cap_emi!$I$14:$I$21&"|"&Calculate_cap_emi!$L$14:$L$21, Calculate_cap_emi!$W$14:$W$21, "Not found", 0),"Rb",_xlfn.XLOOKUP(E8&"|"&B8, Calculate_cap_emi!$I$14:$I$21&"|"&Calculate_cap_emi!$L$14:$L$21, Calculate_cap_emi!$Y$14:$Y$21, "Not found", 0),"Rl",_xlfn.XLOOKUP(E8&"|"&B8, Calculate_cap_emi!$I$14:$I$21&"|"&Calculate_cap_emi!$L$14:$L$21, Calculate_cap_emi!$Z$14:$Z$21, "Not found", 0),0)} -> 8.5 | L8: {=_xlfn.SWITCH(F8,"R",_xlfn.XLOOKUP(E8&"|"&B8, Calculate_cap_emi!$I$14:$I$21&"|"&Calculate_cap_emi!$L$14:$L$21, Calculate_cap_emi!$AC$14:$AC$21, "Not found", 0),"Rb",_xlfn.XLOOKUP(E8&"|"&B8, Calculate_cap_emi!$I$14:$I$21&"|"&Calculate_cap_emi!$L$14:$L$21, Calculate_cap_emi!$AE$14:$AE$21, "Not found", 0),"Rl",_xlfn.XLOOKUP(E8&"|"&B8, Calculate_cap_emi!$I$14:$I$21&"|"&Calculate_cap_emi!$L$14:$L$21, Calculate_cap_emi!$AF$14:$AF$21, "Not found", 0),"HP",_xlfn.XLOOKUP(E8&"|"&B8, Calculate_cap_emi!$I$14:$I$21&"|"&Calculate_cap_emi!$L$14:$L$21, Calculate_cap_emi!$AD$14:$AD$21, "Not found", 0),"HPl",_xlfn.XLOOKUP(E8&"|"&B8, Calculate_cap_emi!$I$14:$I$21&"|"&Calculate_cap_emi!$L$14:$L$21, Calculate_cap_emi!$AG$14:$AG$21, "Not found", 0),"Missing")} -> 905.12944 | Q8: {=_xlfn.SWITCH(F8,"R",_xlfn.XLOOKUP(E8&"|"&B8, Calculate_cap_emi!$I$14:$I$21&"|"&Calculate_cap_emi!$L$14:$L$21, Calculate_cap_emi!$AJ$14:$AJ$21, "Not found", 0),"Rb",_xlfn.XLOOKUP(E8&"|"&B8, Calculate_cap_emi!$I$14:$I$21&"|"&Calculate_cap_emi!$L$14:$L$21, Calculate_cap_emi!$AL$14:$AL$21, "Not found", 0),"Rl",_xlfn.XLOOKUP(E8&"|"&B8, Calculate_cap_emi!$I$14:$I$21&"|"&Calculate_cap_emi!$L$14:$L$21, Calculate_cap_emi!$AM$14:$AM$21, "Not found", 0),"HP",_xlfn.XLOOKUP(E8&"|"&B8, Calculate_cap_emi!$I$14:$I$21&"|"&Calculate_cap_emi!$L$14:$L$21, Calculate_cap_emi!$AK$14:$AK$21, "Not found", 0),"HPl",_xlfn.XLOOKUP(E8&"|"&B8, Calculate_cap_emi!$I$14:$I$21&"|"&Calculate_cap_emi!$L$14:$L$21, Calculate_cap_emi!$AN$14:$AN$21, "Not found", 0),"Missing")} -> 41.12606 | R8: {=_xlfn.SWITCH(F8,"R",_xlfn.XLOOKUP(E8&"|"&B8, Calculate_cap_emi!$I$14:$I$21&"|"&Calculate_cap_emi!$L$14:$L$21, Calculate_cap_emi!$AQ$14:$AQ$21, "Not found", 0),"Rb",_xlfn.XLOOKUP(E8&"|"&B8, Calculate_cap_emi!$I$14:$I$21&"|"&Calculate_cap_emi!$L$14:$L$21, Calculate_cap_emi!$AS$14:$AS$21, "Not found", 0),"Rl",_xlfn.XLOOKUP(E8&"|"&B8, Calculate_cap_emi!$I$14:$I$21&"|"&Calculate_cap_emi!$L$14:$L$21, Calculate_cap_emi!$AT$14:$AT$21, "Not found", 0),"HP",_xlfn.XLOOKUP(E8&"|"&B8, Calculate_cap_emi!$I$14:$I$21&"|"&Calculate_cap_emi!$L$14:$L$21, Calculate_cap_emi!$AR$14:$AR$21, "Not found", 0),"HPl",_xlfn.XLOOKUP(E8&"|"&B8, Calculate_cap_emi!$I$14:$I$21&"|"&Calculate_cap_emi!$L$14:$L$21, Calculate_cap_emi!$AU$14:$AU$21, "Not found", 0),"Missing")} -> 4.9649423 | S8: {=_xlfn.SWITCH(F8,"R",_xlfn.XLOOKUP(E8&"|"&B8, Calculate_cap_emi!$I$14:$I$21&"|"&Calculate_cap_emi!$L$14:$L$21, Calculate_cap_emi!$AX$14:$AX$21, "Not found", 0),"Rb",_xlfn.XLOOKUP(E8&"|"&B8, Calculate_cap_emi!$I$14:$I$21&"|"&Calculate_cap_emi!$L$14:$L$21, Calculate_cap_emi!$AZ$14:$AZ$21, "Not found", 0),"Rl",_xlfn.XLOOKUP(E8&"|"&B8, Calculate_cap_emi!$I$14:$I$21&"|"&Calculate_cap_emi!$L$14:$L$21, Calculate_cap_emi!$BA$14:$BA$21, "Not found", 0),"HP",_xlfn.XLOOKUP(E8&"|"&B8, Calculate_cap_emi!$I$14:$I$21&"|"&Calculate_cap_emi!$L$14:$L$21, Calculate_cap_emi!$AY$14:$AY$21, "Not found", 0),"HPl",_xlfn.XLOOKUP(E8&"|"&B8, Calculate_cap_emi!$I$14:$I$21&"|"&Calculate_cap_emi!$L$14:$L$21, Calculate_cap_emi!$BB$14:$BB$21, "Not found", 0),"Missing")} -> 48.778403 | T8: {=_xlfn.SWITCH(F8,"R",_xlfn.XLOOKUP(E8&"|"&B8, Calculate_cap_emi!$I$14:$I$21&"|"&Calculate_cap_emi!$L$14:$L$21, Calculate_cap_emi!$BE$14:$BE$21, "Not found", 0),"Rb",_xlfn.XLOOKUP(E8&"|"&B8, Calculate_cap_emi!$I$14:$I$21&"|"&Calculate_cap_emi!$L$14:$L$21, Calculate_cap_emi!$BG$14:$BG$21, "Not found", 0),"Rl",_xlfn.XLOOKUP(E8&"|"&B8, Calculate_cap_emi!$I$14:$I$21&"|"&Calculate_cap_emi!$L$14:$L$21, Calculate_cap_emi!$BH$14:$BH$21, "Not found", 0),"HP",_xlfn.XLOOKUP(E8&"|"&B8, Calculate_cap_emi!$I$14:$I$21&"|"&Calculate_cap_emi!$L$14:$L$21, Calculate_cap_emi!$BF$14:$BF$21, "Not found", 0),"HPl",_xlfn.XLOOKUP(E8&"|"&B8, Calculate_cap_emi!$I$14:$I$21&"|"&Calculate_cap_emi!$L$14:$L$21, Calculate_cap_emi!$BI$14:$BI$21, "Not found", 0),"Missing")} -> 0 | U8: {=_xlfn.SWITCH(F8,"R",_xlfn.XLOOKUP(E8&"|"&B8, Calculate_cap_emi_sens!$I$14:$I$21&"|"&Calculate_cap_emi_sens!$L$14:$L$21, Calculate_cap_emi_sens!$AX$14:$AX$21, "Not found", 0),"Rb",_xlfn.XLOOKUP(E8&"|"&B8, Calculate_cap_emi_sens!$I$14:$I$21&"|"&Calculate_cap_emi_sens!$L$14:$L$21, Calculate_cap_emi_sens!$AZ$14:$AZ$21, "Not found", 0),"Rl",_xlfn.XLOOKUP(E8&"|"&B8, Calculate_cap_emi_sens!$I$14:$I$21&"|"&Calculate_cap_emi_sens!$L$14:$L$21, Calculate_cap_emi_sens!$BA$14:$BA$21, "Not found", 0),"HP",_xlfn.XLOOKUP(E8&"|"&B8, Calculate_cap_emi_sens!$I$14:$I$21&"|"&Calculate_cap_emi_sens!$L$14:$L$21, Calculate_cap_emi_sens!$AY$14:$AY$21, "Not found", 0),"HPl",_xlfn.XLOOKUP(E8&"|"&B8, Calculate_cap_emi_sens!$I$14:$I$21&"|"&Calculate_cap_emi_sens!$L$14:$L$21, Calculate_cap_emi_sens!$BB$14:$BB$21, "Not found", 0),"Missing")} -> 48.778403 | V8: {=_xlfn.SWITCH(F8,"R",_xlfn.XLOOKUP(E8&"|"&B8, Calculate_cap_emi_sens!$I$14:$I$21&"|"&Calculate_cap_emi_sens!$L$14:$L$21, Calculate_cap_emi_sens!$BE$14:$BE$21, "Not found", 0),"Rb",_xlfn.XLOOKUP(E8&"|"&B8, Calculate_cap_emi_sens!$I$14:$I$21&"|"&Calculate_cap_emi_sens!$L$14:$L$21, Calculate_cap_emi_sens!$BG$14:$BG$21, "Not found", 0),"Rl",_xlfn.XLOOKUP(E8&"|"&B8, Calculate_cap_emi_sens!$I$14:$I$21&"|"&Calculate_cap_emi_sens!$L$14:$L$21, Calculate_cap_emi_sens!$BH$14:$BH$21, "Not found", 0),"HP",_xlfn.XLOOKUP(E8&"|"&B8, Calculate_cap_emi_sens!$I$14:$I$21&"|"&Calculate_cap_emi_sens!$L$14:$L$21, Calculate_cap_emi_sens!$BF$14:$BF$21, "Not found", 0),"HPl",_xlfn.XLOOKUP(E8&"|"&B8, Calculate_cap_emi_sens!$I$14:$I$21&"|"&Calculate_cap_emi_sens!$L$14:$L$21, Calculate_cap_emi_sens!$BI$14:$BI$21, "Not found", 0),"Missing")} -> 0 | W8: =Results_proc_ener!L8 -> 23714.79 | X8: =Results_proc_ener!M8 -> 0 | Y8: =Results_proc_ener!N8 -> 0 | Z8: =Results_proc_ener!O8 -> 0 | AA8: =Results_proc_ener!P8 -> 0 | AB8: =Results_proc_ener!Q8 -> 870.99418 | AC8: =Results_proc_ener!R8 -> 17.260195 | AD8: =Results_proc_ener!S8 -> 102.23401 | AE8: =Results_proc_ener!T8 -> 0
A9: Mod-H1-Ideal | B9: =_xlfn.TEXTBEFORE(A9, "-", 2) -> Mod-H1 | C9: =_xlfn.TEXTBEFORE(A9, "-", 1) -> Mod | D9: =_xlfn.TEXTAFTER(B9, "-", 1) -> H1 | E9: AK | F9: R | I9: {=_xlfn.SWITCH(F9,"R",_xlfn.XLOOKUP(E9&"|"&B9, Calculate_cap_emi!$I$14:$I$21&"|"&Calculate_cap_emi!$L$14:$L$21, Calculate_cap_emi!$W$14:$W$21, "Not found", 0),"Rb",_xlfn.XLOOKUP(E9&"|"&B9, Calculate_cap_emi!$I$14:$I$21&"|"&Calculate_cap_emi!$L$14:$L$21, Calculate_cap_emi!$Y$14:$Y$21, "Not found", 0),"Rl",_xlfn.XLOOKUP(E9&"|"&B9, Calculate_cap_emi!$I$14:$I$21&"|"&Calculate_cap_emi!$L$14:$L$21, Calculate_cap_emi!$Z$14:$Z$21, "Not found", 0),0)} -> 8.5 | L9: {=_xlfn.SWITCH(F9,"R",_xlfn.XLOOKUP(E9&"|"&B9, Calculate_cap_emi!$I$14:$I$21&"|"&Calculate_cap_emi!$L$14:$L$21, Calculate_cap_emi!$AC$14:$AC$21, "Not found", 0),"Rb",_xlfn.XLOOKUP(E9&"|"&B9, Calculate_cap_emi!$I$14:$I$21&"|"&Calculate_cap_emi!$L$14:$L$21, Calculate_cap_emi!$AE$14:$AE$21, "Not found", 0),"Rl",_xlfn.XLOOKUP(E9&"|"&B9, Calculate_cap_emi!$I$14:$I$21&"|"&Calculate_cap_emi!$L$14:$L$21, Calculate_cap_emi!$AF$14:$AF$21, "Not found", 0),"HP",_xlfn.XLOOKUP(E9&"|"&B9, Calculate_cap_emi!$I$14:$I$21&"|"&Calculate_cap_emi!$L$14:$L$21, Calculate_cap_emi!$AD$14:$AD$21, "Not found", 0),"HPl",_xlfn.XLOOKUP(E9&"|"&B9, Calculate_cap_emi!$I$14:$I$21&"|"&Calculate_cap_emi!$L$14:$L$21, Calculate_cap_emi!$AG$14:$AG$21, "Not found", 0),"Missing")} -> 905.12944 | Q9: {=_xlfn.SWITCH(F9,"R",_xlfn.XLOOKUP(E9&"|"&B9, Calculate_cap_emi!$I$14:$I$21&"|"&Calculate_cap_emi!$L$14:$L$21, Calculate_cap_emi!$AJ$14:$AJ$21, "Not found", 0),"Rb",_xlfn.XLOOKUP(E9&"|"&B9, Calculate_cap_emi!$I$14:$I$21&"|"&Calculate_cap_emi!$L$14:$L$21, Calculate_cap_emi!$AL$14:$AL$21, "Not found", 0),"Rl",_xlfn.XLOOKUP(E9&"|"&B9, Calculate_cap_emi!$I$14:$I$21&"|"&Calculate_cap_emi!$L$14:$L$21, Calculate_cap_emi!$AM$14:$AM$21, "Not found", 0),"HP",_xlfn.XLOOKUP(E9&"|"&B9, Calculate_cap_emi!$I$14:$I$21&"|"&Calculate_cap_emi!$L$14:$L$21, Calculate_cap_emi!$AK$14:$AK$21, "Not found", 0),"HPl",_xlfn.XLOOKUP(E9&"|"&B9, Calculate_cap_emi!$I$14:$I$21&"|"&Calculate_cap_emi!$L$14:$L$21, Calculate_cap_emi!$AN$14:$AN$21, "Not found", 0),"Missing")} -> 41.12606 | R9: {=_xlfn.SWITCH(F9,"R",_xlfn.XLOOKUP(E9&"|"&B9, Calculate_cap_emi!$I$14:$I$21&"|"&Calculate_cap_emi!$L$14:$L$21, Calculate_cap_emi!$AQ$14:$AQ$21, "Not found", 0),"Rb",_xlfn.XLOOKUP(E9&"|"&B9, Calculate_cap_emi!$I$14:$I$21&"|"&Calculate_cap_emi!$L$14:$L$21, Calculate_cap_emi!$AS$14:$AS$21, "Not found", 0),"Rl",_xlfn.XLOOKUP(E9&"|"&B9, Calculate_cap_emi!$I$14:$I$21&"|"&Calculate_cap_emi!$L$14:$L$21, Calculate_cap_emi!$AT$14:$AT$21, "Not found", 0),"HP",_xlfn.XLOOKUP(E9&"|"&B9, Calculate_cap_emi!$I$14:$I$21&"|"&Calculate_cap_emi!$L$14:$L$21, Calculate_cap_emi!$AR$14:$AR$21, "Not found", 0),"HPl",_xlfn.XLOOKUP(E9&"|"&B9, Calculate_cap_emi!$I$14:$I$21&"|"&Calculate_cap_emi!$L$14:$L$21, Calculate_cap_emi!$AU$14:$AU$21, "Not found", 0),"Missing")} -> 4.9649423 | S9: {=_xlfn.SWITCH(F9,"R",_xlfn.XLOOKUP(E9&"|"&B9, Calculate_cap_emi!$I$14:$I$21&"|"&Calculate_cap_emi!$L$14:$L$21, Calculate_cap_emi!$AX$14:$AX$21, "Not found", 0),"Rb",_xlfn.XLOOKUP(E9&"|"&B9, Calculate_cap_emi!$I$14:$I$21&"|"&Calculate_cap_emi!$L$14:$L$21, Calculate_cap_emi!$AZ$14:$AZ$21, "Not found", 0),"Rl",_xlfn.XLOOKUP(E9&"|"&B9, Calculate_cap_emi!$I$14:$I$21&"|"&Calculate_cap_emi!$L$14:$L$21, Calculate_cap_emi!$BA$14:$BA$21, "Not found", 0),"HP",_xlfn.XLOOKUP(E9&"|"&B9, Calculate_cap_emi!$I$14:$I$21&"|"&Calculate_cap_emi!$L$14:$L$21, Calculate_cap_emi!$AY$14:$AY$21, "Not found", 0),"HPl",_xlfn.XLOOKUP(E9&"|"&B9, Calculate_cap_emi!$I$14:$I$21&"|"&Calculate_cap_emi!$L$14:$L$21, Calculate_cap_emi!$BB$14:$BB$21, "Not found", 0),"Missing")} -> 48.778403 | T9: {=_xlfn.SWITCH(F9,"R",_xlfn.XLOOKUP(E9&"|"&B9, Calculate_cap_emi!$I$14:$I$21&"|"&Calculate_cap_emi!$L$14:$L$21, Calculate_cap_emi!$BE$14:$BE$21, "Not found", 0),"Rb",_xlfn.XLOOKUP(E9&"|"&B9, Calculate_cap_emi!$I$14:$I$21&"|"&Calculate_cap_emi!$L$14:$L$21, Calculate_cap_emi!$BG$14:$BG$21, "Not found", 0),"Rl",_xlfn.XLOOKUP(E9&"|"&B9, Calculate_cap_emi!$I$14:$I$21&"|"&Calculate_cap_emi!$L$14:$L$21, Calculate_cap_emi!$BH$14:$BH$21, "Not found", 0),"HP",_xlfn.XLOOKUP(E9&"|"&B9, Calculate_cap_emi!$I$14:$I$21&"|"&Calculate_cap_emi!$L$14:$L$21, Calculate_cap_emi!$BF$14:$BF$21, "Not found", 0),"HPl",_xlfn.XLOOKUP(E9&"|"&B9, Calculate_cap_emi!$I$14:$I$21&"|"&Calculate_cap_emi!$L$14:$L$21, Calculate_cap_emi!$BI$14:$BI$21, "Not found", 0),"Missing")} -> 0 | U9: {=_xlfn.SWITCH(F9,"R",_xlfn.XLOOKUP(E9&"|"&B9, Calculate_cap_emi_sens!$I$14:$I$21&"|"&Calculate_cap_emi_sens!$L$14:$L$21, Calculate_cap_emi_sens!$AX$14:$AX$21, "Not found", 0),"Rb",_xlfn.XLOOKUP(E9&"|"&B9, Calculate_cap_emi_sens!$I$14:$I$21&"|"&Calculate_cap_emi_sens!$L$14:$L$21, Calculate_cap_emi_sens!$AZ$14:$AZ$21, "Not found", 0),"Rl",_xlfn.XLOOKUP(E9&"|"&B9, Calculate_cap_emi_sens!$I$14:$I$21&"|"&Calculate_cap_emi_sens!$L$14:$L$21, Calculate_cap_emi_sens!$BA$14:$BA$21, "Not found", 0),"HP",_xlfn.XLOOKUP(E9&"|"&B9, Calculate_cap_emi_sens!$I$14:$I$21&"|"&Calculate_cap_emi_sens!$L$14:$L$21, Calculate_cap_emi_sens!$AY$14:$AY$21, "Not found", 0),"HPl",_xlfn.XLOOKUP(E9&"|"&B9, Calculate_cap_emi_sens!$I$14:$I$21&"|"&Calculate_cap_emi_sens!$L$14:$L$21, Calculate_cap_emi_sens!$BB$14:$BB$21, "Not found", 0),"Missing")} -> 48.778403 | V9: {=_xlfn.SWITCH(F9,"R",_xlfn.XLOOKUP(E9&"|"&B9, Calculate_cap_emi_sens!$I$14:$I$21&"|"&Calculate_cap_emi_sens!$L$14:$L$21, Calculate_cap_emi_sens!$BE$14:$BE$21, "Not found", 0),"Rb",_xlfn.XLOOKUP(E9&"|"&B9, Calculate_cap_emi_sens!$I$14:$I$21&"|"&Calculate_cap_emi_sens!$L$14:$L$21, Calculate_cap_emi_sens!$BG$14:$BG$21, "Not found", 0),"Rl",_xlfn.XLOOKUP(E9&"|"&B9, Calculate_cap_emi_sens!$I$14:$I$21&"|"&Calculate_cap_emi_sens!$L$14:$L$21, Calculate_cap_emi_sens!$BH$14:$BH$21, "Not found", 0),"HP",_xlfn.XLOOKUP(E9&"|"&B9, Calculate_cap_emi_sens!$I$14:$I$21&"|"&Calculate_cap_emi_sens!$L$14:$L$21, Calculate_cap_emi_sens!$BF$14:$BF$21, "Not found", 0),"HPl",_xlfn.XLOOKUP(E9&"|"&B9, Calculate_cap_emi_sens!$I$14:$I$21&"|"&Calculate_cap_emi_sens!$L$14:$L$21, Calculate_cap_emi_sens!$BI$14:$BI$21, "Not found", 0),"Missing")} -> 0 | W9: =Results_proc_ener!L9 -> 23714.79 | X9: =Results_proc_ener!M9 -> 0 | Y9: =Results_proc_ener!N9 -> 0 | Z9: =Results_proc_ener!O9 -> 0 | AA9: =Results_proc_ener!P9 -> 0 | AB9: =Results_proc_ener!Q9 -> 870.99418 | AC9: =Results_proc_ener!R9 -> 17.260195 | AD9: =Results_proc_ener!S9 -> 102.23401 | AE9: =Results_proc_ener!T9 -> 0
A10: Mass-Nom-Real | B10: =_xlfn.TEXTBEFORE(A10, "-", 2) -> Mass-Nom | C10: =_xlfn.TEXTBEFORE(A10, "-", 1) -> Mass | D10: =_xlfn.TEXTAFTER(B10, "-", 1) -> Nom | E10: CH | F10: R | I10: {=_xlfn.SWITCH(F10,"R",_xlfn.XLOOKUP(E10&"|"&B10, Calculate_cap_emi!$I$14:$I$21&"|"&Calculate_cap_emi!$L$14:$L$21, Calculate_cap_emi!$W$14:$W$21, "Not found", 0),"Rb",_xlfn.XLOOKUP(E10&"|"&B10, Calculate_cap_emi!$I$14:$I$21&"|"&Calculate_cap_emi!$L$14:$L$21, Calculate_cap_emi!$Y$14:$Y$21, "Not found", 0),"Rl",_xlfn.XLOOKUP(E10&"|"&B10, Calculate_cap_emi!$I$14:$I$21&"|"&Calculate_cap_emi!$L$14:$L$21, Calculate_cap_emi!$Z$14:$Z$21, "Not found", 0),0)} -> 15.5 | L10: {=_xlfn.SWITCH(F10,"R",_xlfn.XLOOKUP(E10&"|"&B10, Calculate_cap_emi!$I$14:$I$21&"|"&Calculate_cap_emi!$L$14:$L$21, Calculate_cap_emi!$AC$14:$AC$21, "Not found", 0),"Rb",_xlfn.XLOOKUP(E10&"|"&B10, Calculate_cap_emi!$I$14:$I$21&"|"&Calculate_cap_emi!$L$14:$L$21, Calculate_cap_emi!$AE$14:$AE$21, "Not found", 0),"Rl",_xlfn.XLOOKUP(E10&"|"&B10, Calculate_cap_emi!$I$14:$I$21&"|"&Calculate_cap_emi!$L$14:$L$21, Calculate_cap_emi!$AF$14:$AF$21, "Not found", 0),"HP",_xlfn.XLOOKUP(E10&"|"&B10, Calculate_cap_emi!$I$14:$I$21&"|"&Calculate_cap_emi!$L$14:$L$21, Calculate_cap_emi!$AD$14:$AD$21, "Not found", 0),"HPl",_xlfn.XLOOKUP(E10&"|"&B10, Calculate_cap_emi!$I$14:$I$21&"|"&Calculate_cap_emi!$L$14:$L$21, Calculate_cap_emi!$AG$14:$AG$21, "Not found", 0),"Missing")} -> 1372.8368 | Q10: {=_xlfn.SWITCH(F10,"R",_xlfn.XLOOKUP(E10&"|"&B10, Calculate_cap_emi!$I$14:$I$21&"|"&Calculate_cap_emi!$L$14:$L$21, Calculate_cap_emi!$AJ$14:$AJ$21, "Not found", 0),"Rb",_xlfn.XLOOKUP(E10&"|"&B10, Calculate_cap_emi!$I$14:$I$21&"|"&Calculate_cap_emi!$L$14:$L$21, Calculate_cap_emi!$AL$14:$AL$21, "Not found", 0),"Rl",_xlfn.XLOOKUP(E10&"|"&B10, Calculate_cap_emi!$I$14:$I$21&"|"&Calculate_cap_emi!$L$14:$L$21, Calculate_cap_emi!$AM$14:$AM$21, "Not found", 0),"HP",_xlfn.XLOOKUP(E10&"|"&B10, Calculate_cap_emi!$I$14:$I$21&"|"&Calculate_cap_emi!$L$14:$L$21, Calculate_cap_emi!$AK$14:$AK$21, "Not found", 0),"HPl",_xlfn.XLOOKUP(E10&"|"&B10, Calculate_cap_emi!$I$14:$I$21&"|"&Calculate_cap_emi!$L$14:$L$21, Calculate_cap_emi!$AN$14:$AN$21, "Not found", 0),"Missing")} -> 66.608076 | R10: {=_xlfn.SWITCH(F10,"R",_xlfn.XLOOKUP(E10&"|"&B10, Calculate_cap_emi!$I$14:$I$21&"|"&Calculate_cap_emi!$L$14:$L$21, Calculate_cap_emi!$AQ$14:$AQ$21, "Not found", 0),"Rb",_xlfn.XLOOKUP(E10&"|"&B10, Calculate_cap_emi!$I$14:$I$21&"|"&Calculate_cap_emi!$L$14:$L$21, Calculate_cap_emi!$AS$14:$AS$21, "Not found", 0),"Rl",_xlfn.XLOOKUP(E10&"|"&B10, Calculate_cap_emi!$I$14:$I$21&"|"&Calculate_cap_emi!$L$14:$L$21, Calculate_cap_emi!$AT$14:$AT$21, "Not found", 0),"HP",_xlfn.XLOOKUP(E10&"|"&B10, Calculate_cap_emi!$I$14:$I$21&"|"&Calculate_cap_emi!$L$14:$L$21, Calculate_cap_emi!$AR$14:$AR$21, "Not found", 0),"HPl",_xlfn.XLOOKUP(E10&"|"&B10, Calculate_cap_emi!$I$14:$I$21&"|"&Calculate_cap_emi!$L$14:$L$21, Calculate_cap_emi!$AU$14:$AU$21, "Not found", 0),"Missing")} -> 6.9272476 | S10: {=_xlfn.SWITCH(F10,"R",_xlfn.XLOOKUP(E10&"|"&B10, Calculate_cap_emi!$I$14:$I$21&"|"&Calculate_cap_emi!$L$14:$L$21, Calculate_cap_emi!$AX$14:$AX$21, "Not found", 0),"Rb",_xlfn.XLOOKUP(E10&"|"&B10, Calculate_cap_emi!$I$14:$I$21&"|"&Calculate_cap_emi!$L$14:$L$21, Calculate_cap_emi!$AZ$14:$AZ$21, "Not found", 0),"Rl",_xlfn.XLOOKUP(E10&"|"&B10, Calculate_cap_emi!$I$14:$I$21&"|"&Calculate_cap_emi!$L$14:$L$21, Calculate_cap_emi!$BA$14:$BA$21, "Not found", 0),"HP",_xlfn.XLOOKUP(E10&"|"&B10, Calculate_cap_emi!$I$14:$I$21&"|"&Calculate_cap_emi!$L$14:$L$21, Calculate_cap_emi!$AY$14:$AY$21, "Not found", 0),"HPl",_xlfn.XLOOKUP(E10&"|"&B10, Calculate_cap_emi!$I$14:$I$21&"|"&Calculate_cap_emi!$L$14:$L$21, Calculate_cap_emi!$BB$14:$BB$21, "Not found", 0),"Missing")} -> 78.854138 | T10: {=_xlfn.SWITCH(F10,"R",_xlfn.XLOOKUP(E10&"|"&B10, Calculate_cap_emi!$I$14:$I$21&"|"&Calculate_cap_emi!$L$14:$L$21, Calculate_cap_emi!$BE$14:$BE$21, "Not found", 0),"Rb",_xlfn.XLOOKUP(E10&"|"&B10, Calculate_cap_emi!$I$14:$I$21&"|"&Calculate_cap_emi!$L$14:$L$21, Calculate_cap_emi!$BG$14:$BG$21, "Not found", 0),"Rl",_xlfn.XLOOKUP(E10&"|"&B10, Calculate_cap_emi!$I$14:$I$21&"|"&Calculate_cap_emi!$L$14:$L$21, Calculate_cap_emi!$BH$14:$BH$21, "Not found", 0),"HP",_xlfn.XLOOKUP(E10&"|"&B10, Calculate_cap_emi!$I$14:$I$21&"|"&Calculate_cap_emi!$L$14:$L$21, Calculate_cap_emi!$BF$14:$BF$21, "Not found", 0),"HPl",_xlfn.XLOOKUP(E10&"|"&B10, Calculate_cap_emi!$I$14:$I$21&"|"&Calculate_cap_emi!$L$14:$L$21, Calculate_cap_emi!$BI$14:$BI$21, "Not found", 0),"Missing")} -> 0 | U10: {=_xlfn.SWITCH(F10,"R",_xlfn.XLOOKUP(E10&"|"&B10, Calculate_cap_emi_sens!$I$14:$I$21&"|"&Calculate_cap_emi_sens!$L$14:$L$21, Calculate_cap_emi_sens!$AX$14:$AX$21, "Not found", 0),"Rb",_xlfn.XLOOKUP(E10&"|"&B10, Calculate_cap_emi_sens!$I$14:$I$21&"|"&Calculate_cap_emi_sens!$L$14:$L$21, Calculate_cap_emi_sens!$AZ$14:$AZ$21, "Not found", 0),"Rl",_xlfn.XLOOKUP(E10&"|"&B10, Calculate_cap_emi_sens!$I$14:$I$21&"|"&Calculate_cap_emi_sens!$L$14:$L$21, Calculate_cap_emi_sens!$BA$14:$BA$21, "Not found", 0),"HP",_xlfn.XLOOKUP(E10&"|"&B10, Calculate_cap_emi_sens!$I$14:$I$21&"|"&Calculate_cap_emi_sens!$L$14:$L$21, Calculate_cap_emi_sens!$AY$14:$AY$21, "Not found", 0),"HPl",_xlfn.XLOOKUP(E10&"|"&B10, Calculate_cap_emi_sens!$I$14:$I$21&"|"&Calculate_cap_emi_sens!$L$14:$L$21, Calculate_cap_emi_sens!$BB$14:$BB$21, "Not found", 0),"Missing")} -> 78.854138 | V10: {=_xlfn.SWITCH(F10,"R",_xlfn.XLOOKUP(E10&"|"&B10, Calculate_cap_emi_sens!$I$14:$I$21&"|"&Calculate_cap_emi_sens!$L$14:$L$21, Calculate_cap_emi_sens!$BE$14:$BE$21, "Not found", 0),"Rb",_xlfn.XLOOKUP(E10&"|"&B10, Calculate_cap_emi_sens!$I$14:$I$21&"|"&Calculate_cap_emi_sens!$L$14:$L$21, Calculate_cap_emi_sens!$BG$14:$BG$21, "Not found", 0),"Rl",_xlfn.XLOOKUP(E10&"|"&B10, Calculate_cap_emi_sens!$I$14:$I$21&"|"&Calculate_cap_emi_sens!$L$14:$L$21, Calculate_cap_emi_sens!$BH$14:$BH$21, "Not found", 0),"HP",_xlfn.XLOOKUP(E10&"|"&B10, Calculate_cap_emi_sens!$I$14:$I$21&"|"&Calculate_cap_emi_sens!$L$14:$L$21, Calculate_cap_emi_sens!$BF$14:$BF$21, "Not found", 0),"HPl",_xlfn.XLOOKUP(E10&"|"&B10, Calculate_cap_emi_sens!$I$14:$I$21&"|"&Calculate_cap_emi_sens!$L$14:$L$21, Calculate_cap_emi_sens!$BI$14:$BI$21, "Not found", 0),"Missing")} -> 0 | W10: =Results_proc_ener!L10 -> 36110.498 | X10: =Results_proc_ener!M10 -> 0 | Y10: =Results_proc_ener!N10 -> 0 | Z10: =Results_proc_ener!O10 -> 0 | AA10: =Results_proc_ener!P10 -> 0 | AB10: =Results_proc_ener!Q10 -> 1410.6687 | AC10: =Results_proc_ener!R10 -> 25.98724 | AD10: =Results_proc_ener!S10 -> 148.6705 | AE10: =Results_proc_ener!T10 -> 0
